[34m2018-05-17 10:01:57,320 - rbus-sand calculations - 13491 - INFO - {"message": "Log is saved to /home/yoava/dev/trax_ace_factory/Projects/RBUS_SAND/log.txt", "environment": "DEV", "application": "rbus-sand calculations", "id": "ea03a0c", "process": "10.0.0.87:Local", "platform": "python", "severity": "INFO", "version": "unknown", "size": 273}[0m
[34m2018-05-17 10:01:57,324 - rbus-sand calculations - 13491 - INFO - {"message": "Log initialized with Syslog handler. Running on linux2 ", "environment": "DEV", "application": "rbus-sand calculations", "id": "0c13822", "process": "10.0.0.87:Local", "platform": "python", "severity": "INFO", "version": "unknown", "size": 253}[0m
[34m2018-05-17 10:01:57,325 - rbus-sand calculations - 13491 - INFO - {"message": "Log level set to \"INFO\"", "environment": "DEV", "application": "rbus-sand calculations", "id": "317edaa", "process": "10.0.0.87:Local", "platform": "python", "severity": "INFO", "version": "unknown", "size": 223}[0m
[34m2018-05-17 10:01:57,326 - rbus-sand calculations - 13491 - INFO - {"message": "Environment set to \"Dev\"", "environment": "DEV", "application": "rbus-sand calculations", "id": "4df4e24", "process": "10.0.0.87:Local", "platform": "python", "severity": "INFO", "version": "unknown", "size": 224}[0m
[34m2018-05-17 10:01:57,326 - rbus-sand calculations - 13491 - INFO - {"message": "Process PID is 13491", "environment": "DEV", "application": "rbus-sand calculations", "id": "7bdfe5f", "process": "10.0.0.87:Local", "platform": "python", "severity": "INFO", "version": "unknown", "size": 218}[0m
[34m2018-05-17 10:01:57,327 - rbus-sand calculations - 13491 - INFO - {"message": "Projects data is empty, loading data into memory cache...", "environment": "DEV", "application": "rbus-sand calculations", "id": "083b2d5", "process": "10.0.0.87:Local", "platform": "python", "severity": "INFO", "version": "unknown", "size": 255}[0m
[43m[30m2018-05-17 10:01:57,328 - rbus-sand calculations - 13491 - WARNING - {"message": "Unable to access vault while running in dev environment.", "environment": "DEV", "application": "rbus-sand calculations", "id": "94cc0cb", "process": "10.0.0.87:Local", "platform": "python", "severity": "WARNING", "version": "unknown", "size": 254}[0m
[45m[1m[30m2018-05-17 10:01:57,458 - rbus-sand calculations - 13491 - CRITICAL - {"message": "Unhandled exception hook caught", "environment": "DEV", "application": "rbus-sand calculations", "id": "cce685b", "process": "10.0.0.87:Local", "platform": "python", "severity": "CRITICAL", "version": "unknown", "size": 229}
Traceback (most recent call last):
  File "/home/yoava/dev/trax_ace_factory/Projects/RBUS_SAND/Calculations.py", line 23, in <module>
    data_provider = KEngineDataProvider(project_name)
  File "/home/yoava/miniconda/envs/garage/lib/python2.7/site-packages/Trax/Algo/Calculations/Core/DataProvider.py", line 152, in __init__
    self.orm_session = orm_session if orm_session is not None else OrmSession(project_name, writable=True)
  File "/home/yoava/miniconda/envs/garage/lib/python2.7/site-packages/Trax/Data/Orm/OrmCore.py", line 27, in __init__
    self.session = ProjectsSessions.get_session(project_name, writable, autocommit)
  File "/home/yoava/miniconda/envs/garage/lib/python2.7/site-packages/Trax/Data/Orm/OrmCore.py", line 53, in get_session
    cls.sessions.__setattr__(key_name, InnerOrmSession(project_name, writable, autocommit))
  File "/home/yoava/miniconda/envs/garage/lib/python2.7/site-packages/Trax/Data/Orm/OrmCore.py", line 72, in __init__
    project_instances = ProjectStore.get_project(project_name)
  File "/home/yoava/miniconda/envs/garage/lib/python2.7/site-packages/Trax/Data/Projects/Store.py", line 322, in get_project
    cls._check_invalidation_condition(use_cache)
  File "/home/yoava/miniconda/envs/garage/lib/python2.7/site-packages/Trax/Data/Projects/Store.py", line 99, in _check_invalidation_condition
    cls._load_data()
  File "/home/yoava/miniconda/envs/garage/lib/python2.7/site-packages/Trax/Data/Projects/Store.py", line 63, in _load_data
    for project in projects_cursor:
  File "/home/yoava/miniconda/envs/garage/lib/python2.7/site-packages/pymongo/cursor.py", line 1046, in next
    if len(self.__data) or self._refresh():
  File "/home/yoava/miniconda/envs/garage/lib/python2.7/site-packages/pymongo/cursor.py", line 970, in _refresh
    self.__batch_size))
  File "/home/yoava/miniconda/envs/garage/lib/python2.7/site-packages/pymongo/cursor.py", line 819, in __send_message
    **kwargs)
  File "/home/yoava/miniconda/envs/garage/lib/python2.7/site-packages/pymongo/mongo_client.py", line 749, in _send_message_with_response
    server = topology.select_server(selector)
  File "/home/yoava/miniconda/envs/garage/lib/python2.7/site-packages/pymongo/topology.py", line 141, in select_server
    address))
  File "/home/yoava/miniconda/envs/garage/lib/python2.7/site-packages/pymongo/topology.py", line 126, in select_servers
    self._condition.wait(common.MIN_HEARTBEAT_INTERVAL)
  File "/home/yoava/miniconda/envs/garage/lib/python2.7/threading.py", line 358, in wait
    _sleep(delay)
KeyboardInterrupt[0m
[34m2018-05-17 10:02:07,216 - rbus-sand calculations - 13539 - INFO - {"message": "Log is saved to /home/yoava/dev/trax_ace_factory/Projects/RBUS_SAND/log.txt", "environment": "PROD", "application": "rbus-sand calculations", "id": "ea03a0c", "process": "10.0.0.87:", "platform": "python", "severity": "INFO", "version": "unknown", "size": 269}[0m
[34m2018-05-17 10:02:08,237 - rbus-sand calculations - 13539 - INFO - {"message": "Log initialized with Syslog handler. Running on linux2 ", "environment": "PROD", "application": "rbus-sand calculations", "id": "0c13822", "process": "10.0.0.87:", "platform": "python", "severity": "INFO", "version": "unknown", "size": 249}[0m
[34m2018-05-17 10:02:08,238 - rbus-sand calculations - 13539 - INFO - {"message": "Log level set to \"INFO\"", "environment": "PROD", "application": "rbus-sand calculations", "id": "317edaa", "process": "10.0.0.87:", "platform": "python", "severity": "INFO", "version": "unknown", "size": 219}[0m
[34m2018-05-17 10:02:08,239 - rbus-sand calculations - 13539 - INFO - {"message": "Environment set to \"Prod\"", "environment": "PROD", "application": "rbus-sand calculations", "id": "4df4e24", "process": "10.0.0.87:", "platform": "python", "severity": "INFO", "version": "unknown", "size": 221}[0m
[34m2018-05-17 10:02:08,240 - rbus-sand calculations - 13539 - INFO - {"message": "Process PID is 13539", "environment": "PROD", "application": "rbus-sand calculations", "id": "7bdfe5f", "process": "10.0.0.87:", "platform": "python", "severity": "INFO", "version": "unknown", "size": 214}[0m
[34m2018-05-17 10:02:08,453 - rbus-sand calculations - 13539 - INFO - {"message": "Projects data is empty, loading data into memory cache...", "environment": "PROD", "application": "rbus-sand calculations", "id": "083b2d5", "process": "10.0.0.87:", "platform": "python", "severity": "INFO", "version": "unknown", "size": 251}[0m
[31m[1m2018-05-17 10:02:08,458 - rbus-sand calculations - 13539 - ERROR - {
    "message": "Exception unhandled was caught. Exception is : ",
    "environment": "PROD",
    "application": "rbus-sand calculations",
    "id": "de3406b",
    "process": "10.0.0.87:",
    "platform": "python",
    "severity": "ERROR",
    "version": "unknown",
    "traceback": [
        "Traceback (most recent call last):",
        "  File \"/home/yoava/miniconda/envs/garage/lib/python2.7/site-packages/Trax/Utils/Classes/System.py\", line 19, in get_all_python_files",
        "    all_files = next(os.walk(self.dir_path))[2]",
        "StopIteration"
    ],
    "size": 577
}[0m
[34m2018-05-17 10:02:09,323 - rbus-sand calculations - 13539 - INFO - {"message": "get_credentials: get request returned errors: [u'entry for role yoava@TraxRetail.com not found']", "environment": "PROD", "application": "rbus-sand calculations", "id": "d658487", "process": "10.0.0.87:", "platform": "python", "severity": "INFO", "version": "unknown", "size": 290}[0m
[34m2018-05-17 10:02:10,165 - rbus-sand calculations - 13539 - INFO - {"message": "get_credentials: get request returned errors: [u'entry for role yoava@TraxRetail.com not found']", "environment": "PROD", "application": "rbus-sand calculations", "id": "d658487", "process": "10.0.0.87:", "platform": "python", "severity": "INFO", "version": "unknown", "size": 290}[0m
[43m[30m2018-05-17 10:02:10,165 - rbus-sand calculations - 13539 - WARNING - {"message": "get_credentials: Failed to retrieve credentials from vault: exception is :Login to vault failed 1 tiems. last login resulted errors: [u'entry for role yoava@TraxRetail.com not found']", "environment": "PROD", "application": "rbus-sand calculations", "id": "5d4a35b", "process": "10.0.0.87:", "platform": "python", "severity": "WARNING", "version": "unknown", "size": 377}[0m
[43m[30m2018-05-17 10:02:10,166 - rbus-sand calculations - 13539 - WARNING - {"message": "Traceback (most recent call last):\n  File \"/home/yoava/miniconda/envs/garage/lib/python2.7/site-packages/Trax/Cloud/Services/Connector/Factory.py\", line 87, in get_credentials\n    token = cls.cloud_adapter.get_vault_token(force)\n  File \"/home/yoava/miniconda/envs/garage/lib/python2.7/site-packages/Trax/Cloud/Services/Connector/ConnectorAdapter.py\", line 92, in get_vault_token\n    self._login_vault_request()\n  File \"/home/yoava/miniconda/envs/garage/lib/python2.7/site-packages/Trax/Cloud/Services/Connector/ConnectorAdapter.py\", line 68, in _login_vault_request\n    self._check_for_errors(result, retries)\n  File \"/home/yoava/miniconda/envs/garage/lib/python2.7/site-packages/Trax/Cloud/Services/Connector/ConnectorAdapter.py\", line 82, in _check_for_errors\n    return self._login_vault_request(retries - 1)\n  File \"/home/yoava/miniconda/envs/garage/lib/python2.7/site-packages/Trax/Cloud/Services/Connector/ConnectorAdapter.py\", line 68, in _login_vault_request\n    self._check_for_errors(result, retries)\n  File \"/home/yoava/miniconda/envs/garage/lib/python2.7/site-packages/Trax/Cloud/Services/Connector/ConnectorAdapter.py\", line 83, in _check_for_errors\n    raise Exception(VaultRequest.LOGIN_FAILED_ERR.format(VaultResource.RETRY_AMOUNT, errors))\nException: Login to vault failed 1 tiems. last login resulted errors: [u'entry for role yoava@TraxRetail.com not found']\n", "environment": "PROD", "application": "rbus-sand calculations", "id": "441af55", "process": "10.0.0.87:", "platform": "python", "severity": "WARNING", "version": "unknown", "size": 1598}[0m
[45m[1m[30m2018-05-17 10:02:13,036 - rbus-sand calculations - 13539 - CRITICAL - {"message": "Unhandled exception hook caught", "environment": "PROD", "application": "rbus-sand calculations", "id": "cce685b", "process": "10.0.0.87:", "platform": "python", "severity": "CRITICAL", "version": "unknown", "size": 225}
Traceback (most recent call last):
  File "/home/yoava/dev/trax_ace_factory/Projects/RBUS_SAND/Calculations.py", line 23, in <module>
    data_provider = KEngineDataProvider(project_name)
  File "/home/yoava/miniconda/envs/garage/lib/python2.7/site-packages/Trax/Algo/Calculations/Core/DataProvider.py", line 152, in __init__
    self.orm_session = orm_session if orm_session is not None else OrmSession(project_name, writable=True)
  File "/home/yoava/miniconda/envs/garage/lib/python2.7/site-packages/Trax/Data/Orm/OrmCore.py", line 27, in __init__
    self.session = ProjectsSessions.get_session(project_name, writable, autocommit)
  File "/home/yoava/miniconda/envs/garage/lib/python2.7/site-packages/Trax/Data/Orm/OrmCore.py", line 53, in get_session
    cls.sessions.__setattr__(key_name, InnerOrmSession(project_name, writable, autocommit))
  File "/home/yoava/miniconda/envs/garage/lib/python2.7/site-packages/Trax/Data/Orm/OrmCore.py", line 72, in __init__
    project_instances = ProjectStore.get_project(project_name)
  File "/home/yoava/miniconda/envs/garage/lib/python2.7/site-packages/Trax/Data/Projects/Store.py", line 322, in get_project
    cls._check_invalidation_condition(use_cache)
  File "/home/yoava/miniconda/envs/garage/lib/python2.7/site-packages/Trax/Data/Projects/Store.py", line 99, in _check_invalidation_condition
    cls._load_data()
  File "/home/yoava/miniconda/envs/garage/lib/python2.7/site-packages/Trax/Data/Projects/Store.py", line 63, in _load_data
    for project in projects_cursor:
  File "/home/yoava/miniconda/envs/garage/lib/python2.7/site-packages/pymongo/cursor.py", line 1046, in next
    if len(self.__data) or self._refresh():
  File "/home/yoava/miniconda/envs/garage/lib/python2.7/site-packages/pymongo/cursor.py", line 970, in _refresh
    self.__batch_size))
  File "/home/yoava/miniconda/envs/garage/lib/python2.7/site-packages/pymongo/cursor.py", line 819, in __send_message
    **kwargs)
  File "/home/yoava/miniconda/envs/garage/lib/python2.7/site-packages/pymongo/mongo_client.py", line 749, in _send_message_with_response
    server = topology.select_server(selector)
  File "/home/yoava/miniconda/envs/garage/lib/python2.7/site-packages/pymongo/topology.py", line 141, in select_server
    address))
  File "/home/yoava/miniconda/envs/garage/lib/python2.7/site-packages/pymongo/topology.py", line 126, in select_servers
    self._condition.wait(common.MIN_HEARTBEAT_INTERVAL)
  File "/home/yoava/miniconda/envs/garage/lib/python2.7/threading.py", line 358, in wait
    _sleep(delay)
KeyboardInterrupt[0m
[34m2018-05-17 10:08:13,930 - rbus-sand calculations - 14258 - INFO - {"message": "Log is saved to /home/yoava/dev/trax_ace_factory/Projects/RBUS_SAND/log.txt", "environment": "PROD", "application": "rbus-sand calculations", "cloud": "AWS", "id": "e4f45c9", "process": "10.0.0.87:", "platform": "python", "severity": "INFO", "version": "unknown", "size": 285}[0m
[34m2018-05-17 10:08:14,957 - rbus-sand calculations - 14258 - INFO - {"message": "Log initialized with Syslog handler. Running on linux2 ", "environment": "PROD", "application": "rbus-sand calculations", "cloud": "AWS", "id": "5a0218e", "process": "10.0.0.87:", "platform": "python", "severity": "INFO", "version": "unknown", "size": 265}[0m
[34m2018-05-17 10:08:14,958 - rbus-sand calculations - 14258 - INFO - {"message": "Log level set to \"INFO\"", "environment": "PROD", "application": "rbus-sand calculations", "cloud": "AWS", "id": "cc39983", "process": "10.0.0.87:", "platform": "python", "severity": "INFO", "version": "unknown", "size": 235}[0m
[34m2018-05-17 10:08:14,959 - rbus-sand calculations - 14258 - INFO - {"message": "Environment set to \"Prod\"", "environment": "PROD", "application": "rbus-sand calculations", "cloud": "AWS", "id": "1df03e0", "process": "10.0.0.87:", "platform": "python", "severity": "INFO", "version": "unknown", "size": 237}[0m
[34m2018-05-17 10:08:14,960 - rbus-sand calculations - 14258 - INFO - {"message": "Process PID is 14258", "environment": "PROD", "application": "rbus-sand calculations", "cloud": "AWS", "id": "fff274d", "process": "10.0.0.87:", "platform": "python", "severity": "INFO", "version": "unknown", "size": 230}[0m
[34m2018-05-17 10:08:15,181 - rbus-sand calculations - 14258 - INFO - {"message": "Projects data is empty, loading data into memory cache...", "environment": "PROD", "application": "rbus-sand calculations", "cloud": "AWS", "id": "e08ec6a", "process": "10.0.0.87:", "platform": "python", "severity": "INFO", "version": "unknown", "size": 267}[0m
[34m2018-05-17 10:08:16,083 - rbus-sand calculations - 14258 - INFO - {"message": "get_credentials: get request returned errors: [u'entry for role yoava@TraxRetail.com not found']", "environment": "PROD", "application": "rbus-sand calculations", "cloud": "AWS", "id": "fc56a0b", "process": "10.0.0.87:", "platform": "python", "severity": "INFO", "version": "unknown", "size": 306}[0m
[34m2018-05-17 10:08:16,946 - rbus-sand calculations - 14258 - INFO - {"message": "get_credentials: get request returned errors: [u'entry for role yoava@TraxRetail.com not found']", "environment": "PROD", "application": "rbus-sand calculations", "cloud": "AWS", "id": "fc56a0b", "process": "10.0.0.87:", "platform": "python", "severity": "INFO", "version": "unknown", "size": 306}[0m
[43m[30m2018-05-17 10:08:16,950 - rbus-sand calculations - 14258 - WARNING - {"message": "get_credentials: Failed to retrieve credentials from vault: exception is :Login to vault failed 1 tiems. last login resulted errors: [u'entry for role yoava@TraxRetail.com not found']", "environment": "PROD", "application": "rbus-sand calculations", "cloud": "AWS", "id": "92a0ca6", "process": "10.0.0.87:", "platform": "python", "severity": "WARNING", "version": "unknown", "size": 393}[0m
[43m[30m2018-05-17 10:08:16,955 - rbus-sand calculations - 14258 - WARNING - {"message": "Traceback (most recent call last):\n  File \"/home/yoava/dev/theGarage/Trax/Cloud/Services/Connector/Factory.py\", line 87, in get_credentials\n    token = cls.cloud_adapter.get_vault_token(force)\n  File \"/home/yoava/dev/theGarage/Trax/Cloud/Services/Connector/ConnectorAdapter.py\", line 92, in get_vault_token\n    self._login_vault_request()\n  File \"/home/yoava/dev/theGarage/Trax/Cloud/Services/Connector/ConnectorAdapter.py\", line 68, in _login_vault_request\n    self._check_for_errors(result, retries)\n  File \"/home/yoava/dev/theGarage/Trax/Cloud/Services/Connector/ConnectorAdapter.py\", line 82, in _check_for_errors\n    return self._login_vault_request(retries - 1)\n  File \"/home/yoava/dev/theGarage/Trax/Cloud/Services/Connector/ConnectorAdapter.py\", line 68, in _login_vault_request\n    self._check_for_errors(result, retries)\n  File \"/home/yoava/dev/theGarage/Trax/Cloud/Services/Connector/ConnectorAdapter.py\", line 83, in _check_for_errors\n    raise Exception(VaultRequest.LOGIN_FAILED_ERR.format(VaultResource.RETRY_AMOUNT, errors))\nException: Login to vault failed 1 tiems. last login resulted errors: [u'entry for role yoava@TraxRetail.com not found']\n", "environment": "PROD", "application": "rbus-sand calculations", "cloud": "AWS", "id": "a2d05a8", "process": "10.0.0.87:", "platform": "python", "severity": "WARNING", "version": "unknown", "size": 1398}[0m
[34m2018-05-17 10:08:21,562 - rbus-sand calculations - 14258 - INFO - {"message": "Loaded projects data into memory cache", "environment": "PROD", "application": "rbus-sand calculations", "cloud": "AWS", "id": "07865dd", "process": "10.0.0.87:", "platform": "python", "severity": "INFO", "version": "unknown", "size": 248}[0m
[34m2018-05-17 10:08:22,413 - rbus-sand calculations - 14258 - INFO - {"message": "get_credentials: get request returned errors: [u'entry for role yoava@TraxRetail.com not found']", "environment": "PROD", "application": "rbus-sand calculations", "cloud": "AWS", "id": "fc56a0b", "process": "10.0.0.87:", "platform": "python", "severity": "INFO", "version": "unknown", "size": 306}[0m
[34m2018-05-17 10:08:23,289 - rbus-sand calculations - 14258 - INFO - {"message": "get_credentials: get request returned errors: [u'entry for role yoava@TraxRetail.com not found']", "environment": "PROD", "application": "rbus-sand calculations", "cloud": "AWS", "id": "fc56a0b", "process": "10.0.0.87:", "platform": "python", "severity": "INFO", "version": "unknown", "size": 306}[0m
[43m[30m2018-05-17 10:08:23,293 - rbus-sand calculations - 14258 - WARNING - {"message": "get_credentials: Failed to retrieve credentials from vault: exception is :Login to vault failed 1 tiems. last login resulted errors: [u'entry for role yoava@TraxRetail.com not found']", "environment": "PROD", "application": "rbus-sand calculations", "cloud": "AWS", "id": "92a0ca6", "process": "10.0.0.87:", "platform": "python", "severity": "WARNING", "version": "unknown", "size": 393}[0m
[43m[30m2018-05-17 10:08:23,296 - rbus-sand calculations - 14258 - WARNING - {"message": "Traceback (most recent call last):\n  File \"/home/yoava/dev/theGarage/Trax/Cloud/Services/Connector/Factory.py\", line 87, in get_credentials\n    token = cls.cloud_adapter.get_vault_token(force)\n  File \"/home/yoava/dev/theGarage/Trax/Cloud/Services/Connector/ConnectorAdapter.py\", line 92, in get_vault_token\n    self._login_vault_request()\n  File \"/home/yoava/dev/theGarage/Trax/Cloud/Services/Connector/ConnectorAdapter.py\", line 68, in _login_vault_request\n    self._check_for_errors(result, retries)\n  File \"/home/yoava/dev/theGarage/Trax/Cloud/Services/Connector/ConnectorAdapter.py\", line 82, in _check_for_errors\n    return self._login_vault_request(retries - 1)\n  File \"/home/yoava/dev/theGarage/Trax/Cloud/Services/Connector/ConnectorAdapter.py\", line 68, in _login_vault_request\n    self._check_for_errors(result, retries)\n  File \"/home/yoava/dev/theGarage/Trax/Cloud/Services/Connector/ConnectorAdapter.py\", line 83, in _check_for_errors\n    raise Exception(VaultRequest.LOGIN_FAILED_ERR.format(VaultResource.RETRY_AMOUNT, errors))\nException: Login to vault failed 1 tiems. last login resulted errors: [u'entry for role yoava@TraxRetail.com not found']\n", "environment": "PROD", "application": "rbus-sand calculations", "cloud": "AWS", "id": "a2d05a8", "process": "10.0.0.87:", "platform": "python", "severity": "WARNING", "version": "unknown", "size": 1398}[0m
[34m2018-05-17 10:08:25,380 - rbus-sand calculations - 14258 - INFO - {"message": "get_credentials: get request returned errors: [u'entry for role yoava@TraxRetail.com not found']", "environment": "PROD", "application": "rbus-sand calculations", "cloud": "AWS", "id": "fc56a0b", "process": "10.0.0.87:", "platform": "python", "severity": "INFO", "version": "unknown", "size": 306}[0m
[34m2018-05-17 10:08:26,245 - rbus-sand calculations - 14258 - INFO - {"message": "get_credentials: get request returned errors: [u'entry for role yoava@TraxRetail.com not found']", "environment": "PROD", "application": "rbus-sand calculations", "cloud": "AWS", "id": "fc56a0b", "process": "10.0.0.87:", "platform": "python", "severity": "INFO", "version": "unknown", "size": 306}[0m
[43m[30m2018-05-17 10:08:26,247 - rbus-sand calculations - 14258 - WARNING - {"message": "get_credentials: Failed to retrieve credentials from vault: exception is :Login to vault failed 1 tiems. last login resulted errors: [u'entry for role yoava@TraxRetail.com not found']", "environment": "PROD", "application": "rbus-sand calculations", "cloud": "AWS", "id": "92a0ca6", "process": "10.0.0.87:", "platform": "python", "severity": "WARNING", "version": "unknown", "size": 393}[0m
[43m[30m2018-05-17 10:08:26,249 - rbus-sand calculations - 14258 - WARNING - {"message": "Traceback (most recent call last):\n  File \"/home/yoava/dev/theGarage/Trax/Cloud/Services/Connector/Factory.py\", line 87, in get_credentials\n    token = cls.cloud_adapter.get_vault_token(force)\n  File \"/home/yoava/dev/theGarage/Trax/Cloud/Services/Connector/ConnectorAdapter.py\", line 92, in get_vault_token\n    self._login_vault_request()\n  File \"/home/yoava/dev/theGarage/Trax/Cloud/Services/Connector/ConnectorAdapter.py\", line 68, in _login_vault_request\n    self._check_for_errors(result, retries)\n  File \"/home/yoava/dev/theGarage/Trax/Cloud/Services/Connector/ConnectorAdapter.py\", line 82, in _check_for_errors\n    return self._login_vault_request(retries - 1)\n  File \"/home/yoava/dev/theGarage/Trax/Cloud/Services/Connector/ConnectorAdapter.py\", line 68, in _login_vault_request\n    self._check_for_errors(result, retries)\n  File \"/home/yoava/dev/theGarage/Trax/Cloud/Services/Connector/ConnectorAdapter.py\", line 83, in _check_for_errors\n    raise Exception(VaultRequest.LOGIN_FAILED_ERR.format(VaultResource.RETRY_AMOUNT, errors))\nException: Login to vault failed 1 tiems. last login resulted errors: [u'entry for role yoava@TraxRetail.com not found']\n", "environment": "PROD", "application": "rbus-sand calculations", "cloud": "AWS", "id": "a2d05a8", "process": "10.0.0.87:", "platform": "python", "severity": "WARNING", "version": "unknown", "size": 1398}[0m
[34m2018-05-17 10:08:41,113 - rbus-sand calculations - 14343 - INFO - {"message": "Log is saved to /home/yoava/dev/trax_ace_factory/Projects/RBUS_SAND/log.txt", "environment": "PROD", "application": "rbus-sand calculations", "cloud": "AWS", "id": "e4f45c9", "process": "10.0.0.87:", "platform": "python", "severity": "INFO", "version": "unknown", "size": 285}[0m
[34m2018-05-17 10:08:42,176 - rbus-sand calculations - 14343 - INFO - {"message": "Log initialized with Syslog handler. Running on linux2 ", "environment": "PROD", "application": "rbus-sand calculations", "cloud": "AWS", "id": "5a0218e", "process": "10.0.0.87:", "platform": "python", "severity": "INFO", "version": "unknown", "size": 265}[0m
[34m2018-05-17 10:08:42,180 - rbus-sand calculations - 14343 - INFO - {"message": "Log level set to \"INFO\"", "environment": "PROD", "application": "rbus-sand calculations", "cloud": "AWS", "id": "cc39983", "process": "10.0.0.87:", "platform": "python", "severity": "INFO", "version": "unknown", "size": 235}[0m
[34m2018-05-17 10:08:42,185 - rbus-sand calculations - 14343 - INFO - {"message": "Environment set to \"Prod\"", "environment": "PROD", "application": "rbus-sand calculations", "cloud": "AWS", "id": "1df03e0", "process": "10.0.0.87:", "platform": "python", "severity": "INFO", "version": "unknown", "size": 237}[0m
[34m2018-05-17 10:08:42,188 - rbus-sand calculations - 14343 - INFO - {"message": "Process PID is 14343", "environment": "PROD", "application": "rbus-sand calculations", "cloud": "AWS", "id": "fff274d", "process": "10.0.0.87:", "platform": "python", "severity": "INFO", "version": "unknown", "size": 230}[0m
[34m2018-05-17 10:08:42,399 - rbus-sand calculations - 14343 - INFO - {"message": "Projects data is empty, loading data into memory cache...", "environment": "PROD", "application": "rbus-sand calculations", "cloud": "AWS", "id": "e08ec6a", "process": "10.0.0.87:", "platform": "python", "severity": "INFO", "version": "unknown", "size": 267}[0m
[34m2018-05-17 10:08:43,309 - rbus-sand calculations - 14343 - INFO - {"message": "get_credentials: get request returned errors: [u'entry for role yoava@TraxRetail.com not found']", "environment": "PROD", "application": "rbus-sand calculations", "cloud": "AWS", "id": "fc56a0b", "process": "10.0.0.87:", "platform": "python", "severity": "INFO", "version": "unknown", "size": 306}[0m
[34m2018-05-17 10:08:44,209 - rbus-sand calculations - 14343 - INFO - {"message": "get_credentials: get request returned errors: [u'entry for role yoava@TraxRetail.com not found']", "environment": "PROD", "application": "rbus-sand calculations", "cloud": "AWS", "id": "fc56a0b", "process": "10.0.0.87:", "platform": "python", "severity": "INFO", "version": "unknown", "size": 306}[0m
[43m[30m2018-05-17 10:08:44,216 - rbus-sand calculations - 14343 - WARNING - {"message": "get_credentials: Failed to retrieve credentials from vault: exception is :Login to vault failed 1 tiems. last login resulted errors: [u'entry for role yoava@TraxRetail.com not found']", "environment": "PROD", "application": "rbus-sand calculations", "cloud": "AWS", "id": "92a0ca6", "process": "10.0.0.87:", "platform": "python", "severity": "WARNING", "version": "unknown", "size": 393}[0m
[43m[30m2018-05-17 10:08:44,225 - rbus-sand calculations - 14343 - WARNING - {"message": "Traceback (most recent call last):\n  File \"/home/yoava/dev/theGarage/Trax/Cloud/Services/Connector/Factory.py\", line 87, in get_credentials\n    token = cls.cloud_adapter.get_vault_token(force)\n  File \"/home/yoava/dev/theGarage/Trax/Cloud/Services/Connector/ConnectorAdapter.py\", line 92, in get_vault_token\n    self._login_vault_request()\n  File \"/home/yoava/dev/theGarage/Trax/Cloud/Services/Connector/ConnectorAdapter.py\", line 68, in _login_vault_request\n    self._check_for_errors(result, retries)\n  File \"/home/yoava/dev/theGarage/Trax/Cloud/Services/Connector/ConnectorAdapter.py\", line 82, in _check_for_errors\n    return self._login_vault_request(retries - 1)\n  File \"/home/yoava/dev/theGarage/Trax/Cloud/Services/Connector/ConnectorAdapter.py\", line 68, in _login_vault_request\n    self._check_for_errors(result, retries)\n  File \"/home/yoava/dev/theGarage/Trax/Cloud/Services/Connector/ConnectorAdapter.py\", line 83, in _check_for_errors\n    raise Exception(VaultRequest.LOGIN_FAILED_ERR.format(VaultResource.RETRY_AMOUNT, errors))\nException: Login to vault failed 1 tiems. last login resulted errors: [u'entry for role yoava@TraxRetail.com not found']\n", "environment": "PROD", "application": "rbus-sand calculations", "cloud": "AWS", "id": "a2d05a8", "process": "10.0.0.87:", "platform": "python", "severity": "WARNING", "version": "unknown", "size": 1398}[0m
[34m2018-05-17 10:08:49,945 - rbus-sand calculations - 14343 - INFO - {"message": "Loaded projects data into memory cache", "environment": "PROD", "application": "rbus-sand calculations", "cloud": "AWS", "id": "07865dd", "process": "10.0.0.87:", "platform": "python", "severity": "INFO", "version": "unknown", "size": 248}[0m
[34m2018-05-17 10:08:50,844 - rbus-sand calculations - 14343 - INFO - {"message": "get_credentials: get request returned errors: [u'entry for role yoava@TraxRetail.com not found']", "environment": "PROD", "application": "rbus-sand calculations", "cloud": "AWS", "id": "fc56a0b", "process": "10.0.0.87:", "platform": "python", "severity": "INFO", "version": "unknown", "size": 306}[0m
[34m2018-05-17 10:08:51,754 - rbus-sand calculations - 14343 - INFO - {"message": "get_credentials: get request returned errors: [u'entry for role yoava@TraxRetail.com not found']", "environment": "PROD", "application": "rbus-sand calculations", "cloud": "AWS", "id": "fc56a0b", "process": "10.0.0.87:", "platform": "python", "severity": "INFO", "version": "unknown", "size": 306}[0m
[43m[30m2018-05-17 10:08:51,762 - rbus-sand calculations - 14343 - WARNING - {"message": "get_credentials: Failed to retrieve credentials from vault: exception is :Login to vault failed 1 tiems. last login resulted errors: [u'entry for role yoava@TraxRetail.com not found']", "environment": "PROD", "application": "rbus-sand calculations", "cloud": "AWS", "id": "92a0ca6", "process": "10.0.0.87:", "platform": "python", "severity": "WARNING", "version": "unknown", "size": 393}[0m
[43m[30m2018-05-17 10:08:51,769 - rbus-sand calculations - 14343 - WARNING - {"message": "Traceback (most recent call last):\n  File \"/home/yoava/dev/theGarage/Trax/Cloud/Services/Connector/Factory.py\", line 87, in get_credentials\n    token = cls.cloud_adapter.get_vault_token(force)\n  File \"/home/yoava/dev/theGarage/Trax/Cloud/Services/Connector/ConnectorAdapter.py\", line 92, in get_vault_token\n    self._login_vault_request()\n  File \"/home/yoava/dev/theGarage/Trax/Cloud/Services/Connector/ConnectorAdapter.py\", line 68, in _login_vault_request\n    self._check_for_errors(result, retries)\n  File \"/home/yoava/dev/theGarage/Trax/Cloud/Services/Connector/ConnectorAdapter.py\", line 82, in _check_for_errors\n    return self._login_vault_request(retries - 1)\n  File \"/home/yoava/dev/theGarage/Trax/Cloud/Services/Connector/ConnectorAdapter.py\", line 68, in _login_vault_request\n    self._check_for_errors(result, retries)\n  File \"/home/yoava/dev/theGarage/Trax/Cloud/Services/Connector/ConnectorAdapter.py\", line 83, in _check_for_errors\n    raise Exception(VaultRequest.LOGIN_FAILED_ERR.format(VaultResource.RETRY_AMOUNT, errors))\nException: Login to vault failed 1 tiems. last login resulted errors: [u'entry for role yoava@TraxRetail.com not found']\n", "environment": "PROD", "application": "rbus-sand calculations", "cloud": "AWS", "id": "a2d05a8", "process": "10.0.0.87:", "platform": "python", "severity": "WARNING", "version": "unknown", "size": 1398}[0m
[34m2018-05-17 10:08:55,096 - rbus-sand calculations - 14343 - INFO - {"message": "get_credentials: get request returned errors: [u'entry for role yoava@TraxRetail.com not found']", "environment": "PROD", "application": "rbus-sand calculations", "cloud": "AWS", "id": "fc56a0b", "process": "10.0.0.87:", "platform": "python", "severity": "INFO", "version": "unknown", "size": 306}[0m
[34m2018-05-17 10:08:56,081 - rbus-sand calculations - 14343 - INFO - {"message": "get_credentials: get request returned errors: [u'entry for role yoava@TraxRetail.com not found']", "environment": "PROD", "application": "rbus-sand calculations", "cloud": "AWS", "id": "fc56a0b", "process": "10.0.0.87:", "platform": "python", "severity": "INFO", "version": "unknown", "size": 306}[0m
[43m[30m2018-05-17 10:08:56,092 - rbus-sand calculations - 14343 - WARNING - {"message": "get_credentials: Failed to retrieve credentials from vault: exception is :Login to vault failed 1 tiems. last login resulted errors: [u'entry for role yoava@TraxRetail.com not found']", "environment": "PROD", "application": "rbus-sand calculations", "cloud": "AWS", "id": "92a0ca6", "process": "10.0.0.87:", "platform": "python", "severity": "WARNING", "version": "unknown", "size": 393}[0m
[43m[30m2018-05-17 10:08:56,097 - rbus-sand calculations - 14343 - WARNING - {"message": "Traceback (most recent call last):\n  File \"/home/yoava/dev/theGarage/Trax/Cloud/Services/Connector/Factory.py\", line 87, in get_credentials\n    token = cls.cloud_adapter.get_vault_token(force)\n  File \"/home/yoava/dev/theGarage/Trax/Cloud/Services/Connector/ConnectorAdapter.py\", line 92, in get_vault_token\n    self._login_vault_request()\n  File \"/home/yoava/dev/theGarage/Trax/Cloud/Services/Connector/ConnectorAdapter.py\", line 68, in _login_vault_request\n    self._check_for_errors(result, retries)\n  File \"/home/yoava/dev/theGarage/Trax/Cloud/Services/Connector/ConnectorAdapter.py\", line 82, in _check_for_errors\n    return self._login_vault_request(retries - 1)\n  File \"/home/yoava/dev/theGarage/Trax/Cloud/Services/Connector/ConnectorAdapter.py\", line 68, in _login_vault_request\n    self._check_for_errors(result, retries)\n  File \"/home/yoava/dev/theGarage/Trax/Cloud/Services/Connector/ConnectorAdapter.py\", line 83, in _check_for_errors\n    raise Exception(VaultRequest.LOGIN_FAILED_ERR.format(VaultResource.RETRY_AMOUNT, errors))\nException: Login to vault failed 1 tiems. last login resulted errors: [u'entry for role yoava@TraxRetail.com not found']\n", "environment": "PROD", "application": "rbus-sand calculations", "cloud": "AWS", "id": "a2d05a8", "process": "10.0.0.87:", "platform": "python", "severity": "WARNING", "version": "unknown", "size": 1398}[0m
[34m2018-05-17 10:09:18,446 - rbus-sand calculations - 14400 - INFO - {"message": "Log is saved to /home/yoava/dev/trax_ace_factory/Projects/RBUS_SAND/log.txt", "environment": "PROD", "application": "rbus-sand calculations", "cloud": "AWS", "id": "e4f45c9", "process": "10.0.0.87:", "platform": "python", "severity": "INFO", "version": "unknown", "size": 285}[0m
[34m2018-05-17 10:09:19,501 - rbus-sand calculations - 14400 - INFO - {"message": "Log initialized with Syslog handler. Running on linux2 ", "environment": "PROD", "application": "rbus-sand calculations", "cloud": "AWS", "id": "5a0218e", "process": "10.0.0.87:", "platform": "python", "severity": "INFO", "version": "unknown", "size": 265}[0m
[34m2018-05-17 10:09:19,504 - rbus-sand calculations - 14400 - INFO - {"message": "Log level set to \"INFO\"", "environment": "PROD", "application": "rbus-sand calculations", "cloud": "AWS", "id": "cc39983", "process": "10.0.0.87:", "platform": "python", "severity": "INFO", "version": "unknown", "size": 235}[0m
[34m2018-05-17 10:09:19,507 - rbus-sand calculations - 14400 - INFO - {"message": "Environment set to \"Prod\"", "environment": "PROD", "application": "rbus-sand calculations", "cloud": "AWS", "id": "1df03e0", "process": "10.0.0.87:", "platform": "python", "severity": "INFO", "version": "unknown", "size": 237}[0m
[34m2018-05-17 10:09:19,509 - rbus-sand calculations - 14400 - INFO - {"message": "Process PID is 14400", "environment": "PROD", "application": "rbus-sand calculations", "cloud": "AWS", "id": "fff274d", "process": "10.0.0.87:", "platform": "python", "severity": "INFO", "version": "unknown", "size": 230}[0m
[34m2018-05-17 10:09:19,732 - rbus-sand calculations - 14400 - INFO - {"message": "Projects data is empty, loading data into memory cache...", "environment": "PROD", "application": "rbus-sand calculations", "cloud": "AWS", "id": "e08ec6a", "process": "10.0.0.87:", "platform": "python", "severity": "INFO", "version": "unknown", "size": 267}[0m
[34m2018-05-17 10:09:20,676 - rbus-sand calculations - 14400 - INFO - {"message": "get_credentials: get request returned errors: [u'entry for role yoava@TraxRetail.com not found']", "environment": "PROD", "application": "rbus-sand calculations", "cloud": "AWS", "id": "fc56a0b", "process": "10.0.0.87:", "platform": "python", "severity": "INFO", "version": "unknown", "size": 306}[0m
[34m2018-05-17 10:09:21,615 - rbus-sand calculations - 14400 - INFO - {"message": "get_credentials: get request returned errors: [u'entry for role yoava@TraxRetail.com not found']", "environment": "PROD", "application": "rbus-sand calculations", "cloud": "AWS", "id": "fc56a0b", "process": "10.0.0.87:", "platform": "python", "severity": "INFO", "version": "unknown", "size": 306}[0m
[43m[30m2018-05-17 10:09:21,622 - rbus-sand calculations - 14400 - WARNING - {"message": "get_credentials: Failed to retrieve credentials from vault: exception is :Login to vault failed 1 tiems. last login resulted errors: [u'entry for role yoava@TraxRetail.com not found']", "environment": "PROD", "application": "rbus-sand calculations", "cloud": "AWS", "id": "92a0ca6", "process": "10.0.0.87:", "platform": "python", "severity": "WARNING", "version": "unknown", "size": 393}[0m
[43m[30m2018-05-17 10:09:21,630 - rbus-sand calculations - 14400 - WARNING - {"message": "Traceback (most recent call last):\n  File \"/home/yoava/dev/theGarage/Trax/Cloud/Services/Connector/Factory.py\", line 87, in get_credentials\n    token = cls.cloud_adapter.get_vault_token(force)\n  File \"/home/yoava/dev/theGarage/Trax/Cloud/Services/Connector/ConnectorAdapter.py\", line 92, in get_vault_token\n    self._login_vault_request()\n  File \"/home/yoava/dev/theGarage/Trax/Cloud/Services/Connector/ConnectorAdapter.py\", line 68, in _login_vault_request\n    self._check_for_errors(result, retries)\n  File \"/home/yoava/dev/theGarage/Trax/Cloud/Services/Connector/ConnectorAdapter.py\", line 82, in _check_for_errors\n    return self._login_vault_request(retries - 1)\n  File \"/home/yoava/dev/theGarage/Trax/Cloud/Services/Connector/ConnectorAdapter.py\", line 68, in _login_vault_request\n    self._check_for_errors(result, retries)\n  File \"/home/yoava/dev/theGarage/Trax/Cloud/Services/Connector/ConnectorAdapter.py\", line 83, in _check_for_errors\n    raise Exception(VaultRequest.LOGIN_FAILED_ERR.format(VaultResource.RETRY_AMOUNT, errors))\nException: Login to vault failed 1 tiems. last login resulted errors: [u'entry for role yoava@TraxRetail.com not found']\n", "environment": "PROD", "application": "rbus-sand calculations", "cloud": "AWS", "id": "a2d05a8", "process": "10.0.0.87:", "platform": "python", "severity": "WARNING", "version": "unknown", "size": 1398}[0m
[34m2018-05-17 10:09:31,133 - rbus-sand calculations - 14451 - INFO - {"message": "Log is saved to /home/yoava/dev/trax_ace_factory/Projects/RBUS_SAND/log.txt", "environment": "PROD", "application": "rbus-sand calculations", "cloud": "AWS", "id": "e4f45c9", "process": "10.0.0.87:", "platform": "python", "severity": "INFO", "version": "unknown", "size": 285}[0m
[34m2018-05-17 10:09:32,197 - rbus-sand calculations - 14451 - INFO - {"message": "Log initialized with Syslog handler. Running on linux2 ", "environment": "PROD", "application": "rbus-sand calculations", "cloud": "AWS", "id": "5a0218e", "process": "10.0.0.87:", "platform": "python", "severity": "INFO", "version": "unknown", "size": 265}[0m
[34m2018-05-17 10:09:32,200 - rbus-sand calculations - 14451 - INFO - {"message": "Log level set to \"INFO\"", "environment": "PROD", "application": "rbus-sand calculations", "cloud": "AWS", "id": "cc39983", "process": "10.0.0.87:", "platform": "python", "severity": "INFO", "version": "unknown", "size": 235}[0m
[34m2018-05-17 10:09:32,202 - rbus-sand calculations - 14451 - INFO - {"message": "Environment set to \"Prod\"", "environment": "PROD", "application": "rbus-sand calculations", "cloud": "AWS", "id": "1df03e0", "process": "10.0.0.87:", "platform": "python", "severity": "INFO", "version": "unknown", "size": 237}[0m
[34m2018-05-17 10:09:32,207 - rbus-sand calculations - 14451 - INFO - {"message": "Process PID is 14451", "environment": "PROD", "application": "rbus-sand calculations", "cloud": "AWS", "id": "fff274d", "process": "10.0.0.87:", "platform": "python", "severity": "INFO", "version": "unknown", "size": 230}[0m
[34m2018-05-17 10:10:03,278 - rbus-sand calculations - 14451 - INFO - {"message": "Projects data is empty, loading data into memory cache...", "environment": "PROD", "application": "rbus-sand calculations", "cloud": "AWS", "id": "e08ec6a", "process": "10.0.0.87:", "platform": "python", "severity": "INFO", "version": "unknown", "size": 267}[0m
[34m2018-05-17 10:10:04,262 - rbus-sand calculations - 14451 - INFO - {"message": "get_credentials: get request returned errors: [u'entry for role yoava@TraxRetail.com not found']", "environment": "PROD", "application": "rbus-sand calculations", "cloud": "AWS", "id": "fc56a0b", "process": "10.0.0.87:", "platform": "python", "severity": "INFO", "version": "unknown", "size": 306}[0m
[34m2018-05-17 10:10:05,192 - rbus-sand calculations - 14451 - INFO - {"message": "get_credentials: get request returned errors: [u'entry for role yoava@TraxRetail.com not found']", "environment": "PROD", "application": "rbus-sand calculations", "cloud": "AWS", "id": "fc56a0b", "process": "10.0.0.87:", "platform": "python", "severity": "INFO", "version": "unknown", "size": 306}[0m
[43m[30m2018-05-17 10:10:05,204 - rbus-sand calculations - 14451 - WARNING - {"message": "get_credentials: Failed to retrieve credentials from vault: exception is :Login to vault failed 1 tiems. last login resulted errors: [u'entry for role yoava@TraxRetail.com not found']", "environment": "PROD", "application": "rbus-sand calculations", "cloud": "AWS", "id": "92a0ca6", "process": "10.0.0.87:", "platform": "python", "severity": "WARNING", "version": "unknown", "size": 393}[0m
[43m[30m2018-05-17 10:10:05,217 - rbus-sand calculations - 14451 - WARNING - {"message": "Traceback (most recent call last):\n  File \"/home/yoava/dev/theGarage/Trax/Cloud/Services/Connector/Factory.py\", line 87, in get_credentials\n    token = cls.cloud_adapter.get_vault_token(force)\n  File \"/home/yoava/dev/theGarage/Trax/Cloud/Services/Connector/ConnectorAdapter.py\", line 92, in get_vault_token\n    self._login_vault_request()\n  File \"/home/yoava/dev/theGarage/Trax/Cloud/Services/Connector/ConnectorAdapter.py\", line 68, in _login_vault_request\n    self._check_for_errors(result, retries)\n  File \"/home/yoava/dev/theGarage/Trax/Cloud/Services/Connector/ConnectorAdapter.py\", line 82, in _check_for_errors\n    return self._login_vault_request(retries - 1)\n  File \"/home/yoava/dev/theGarage/Trax/Cloud/Services/Connector/ConnectorAdapter.py\", line 68, in _login_vault_request\n    self._check_for_errors(result, retries)\n  File \"/home/yoava/dev/theGarage/Trax/Cloud/Services/Connector/ConnectorAdapter.py\", line 83, in _check_for_errors\n    raise Exception(VaultRequest.LOGIN_FAILED_ERR.format(VaultResource.RETRY_AMOUNT, errors))\nException: Login to vault failed 1 tiems. last login resulted errors: [u'entry for role yoava@TraxRetail.com not found']\n", "environment": "PROD", "application": "rbus-sand calculations", "cloud": "AWS", "id": "a2d05a8", "process": "10.0.0.87:", "platform": "python", "severity": "WARNING", "version": "unknown", "size": 1398}[0m
[34m2018-05-17 10:10:12,456 - rbus-sand calculations - 14540 - INFO - {"message": "Log is saved to /home/yoava/dev/trax_ace_factory/Projects/RBUS_SAND/log.txt", "environment": "PROD", "application": "rbus-sand calculations", "cloud": "AWS", "id": "e4f45c9", "process": "10.0.0.87:", "platform": "python", "severity": "INFO", "version": "unknown", "size": 285}[0m
[34m2018-05-17 10:10:13,491 - rbus-sand calculations - 14540 - INFO - {"message": "Log initialized with Syslog handler. Running on linux2 ", "environment": "PROD", "application": "rbus-sand calculations", "cloud": "AWS", "id": "5a0218e", "process": "10.0.0.87:", "platform": "python", "severity": "INFO", "version": "unknown", "size": 265}[0m
[34m2018-05-17 10:10:13,494 - rbus-sand calculations - 14540 - INFO - {"message": "Log level set to \"INFO\"", "environment": "PROD", "application": "rbus-sand calculations", "cloud": "AWS", "id": "cc39983", "process": "10.0.0.87:", "platform": "python", "severity": "INFO", "version": "unknown", "size": 235}[0m
[34m2018-05-17 10:10:13,498 - rbus-sand calculations - 14540 - INFO - {"message": "Environment set to \"Prod\"", "environment": "PROD", "application": "rbus-sand calculations", "cloud": "AWS", "id": "1df03e0", "process": "10.0.0.87:", "platform": "python", "severity": "INFO", "version": "unknown", "size": 237}[0m
[34m2018-05-17 10:10:13,500 - rbus-sand calculations - 14540 - INFO - {"message": "Process PID is 14540", "environment": "PROD", "application": "rbus-sand calculations", "cloud": "AWS", "id": "fff274d", "process": "10.0.0.87:", "platform": "python", "severity": "INFO", "version": "unknown", "size": 230}[0m
[34m2018-05-17 10:11:11,155 - rbus-sand calculations - 14540 - INFO - {"message": "Projects data is empty, loading data into memory cache...", "environment": "PROD", "application": "rbus-sand calculations", "cloud": "AWS", "id": "e08ec6a", "process": "10.0.0.87:", "platform": "python", "severity": "INFO", "version": "unknown", "size": 267}[0m
[34m2018-05-17 10:12:14,300 - rbus-sand calculations - 14540 - INFO - {"message": "get_credentials: get request returned errors: [u'entry for role yoava@TraxRetail.com not found']", "environment": "PROD", "application": "rbus-sand calculations", "cloud": "AWS", "id": "fc56a0b", "process": "10.0.0.87:", "platform": "python", "severity": "INFO", "version": "unknown", "size": 306}[0m
[34m2018-05-17 10:12:15,216 - rbus-sand calculations - 14540 - INFO - {"message": "get_credentials: get request returned errors: [u'entry for role yoava@TraxRetail.com not found']", "environment": "PROD", "application": "rbus-sand calculations", "cloud": "AWS", "id": "fc56a0b", "process": "10.0.0.87:", "platform": "python", "severity": "INFO", "version": "unknown", "size": 306}[0m
[43m[30m2018-05-17 10:12:15,219 - rbus-sand calculations - 14540 - WARNING - {"message": "get_credentials: Failed to retrieve credentials from vault: exception is :Login to vault failed 1 tiems. last login resulted errors: [u'entry for role yoava@TraxRetail.com not found']", "environment": "PROD", "application": "rbus-sand calculations", "cloud": "AWS", "id": "92a0ca6", "process": "10.0.0.87:", "platform": "python", "severity": "WARNING", "version": "unknown", "size": 393}[0m
[43m[30m2018-05-17 10:12:15,223 - rbus-sand calculations - 14540 - WARNING - {"message": "Traceback (most recent call last):\n  File \"/home/yoava/dev/theGarage/Trax/Cloud/Services/Connector/Factory.py\", line 87, in get_credentials\n    token = cls.cloud_adapter.get_vault_token(force)\n  File \"/home/yoava/dev/theGarage/Trax/Cloud/Services/Connector/ConnectorAdapter.py\", line 92, in get_vault_token\n    self._login_vault_request()\n  File \"/home/yoava/dev/theGarage/Trax/Cloud/Services/Connector/ConnectorAdapter.py\", line 68, in _login_vault_request\n    self._check_for_errors(result, retries)\n  File \"/home/yoava/dev/theGarage/Trax/Cloud/Services/Connector/ConnectorAdapter.py\", line 82, in _check_for_errors\n    return self._login_vault_request(retries - 1)\n  File \"/home/yoava/dev/theGarage/Trax/Cloud/Services/Connector/ConnectorAdapter.py\", line 68, in _login_vault_request\n    self._check_for_errors(result, retries)\n  File \"/home/yoava/dev/theGarage/Trax/Cloud/Services/Connector/ConnectorAdapter.py\", line 83, in _check_for_errors\n    raise Exception(VaultRequest.LOGIN_FAILED_ERR.format(VaultResource.RETRY_AMOUNT, errors))\nException: Login to vault failed 1 tiems. last login resulted errors: [u'entry for role yoava@TraxRetail.com not found']\n", "environment": "PROD", "application": "rbus-sand calculations", "cloud": "AWS", "id": "a2d05a8", "process": "10.0.0.87:", "platform": "python", "severity": "WARNING", "version": "unknown", "size": 1398}[0m
[34m2018-05-17 10:12:47,284 - rbus-sand calculations - 15398 - INFO - {"message": "Log is saved to /home/yoava/dev/trax_ace_factory/Projects/RBUS_SAND/log.txt", "environment": "PROD", "application": "rbus-sand calculations", "id": "ea03a0c", "process": "10.0.0.87:", "platform": "python", "severity": "INFO", "version": "unknown", "size": 269}[0m
[34m2018-05-17 10:12:48,339 - rbus-sand calculations - 15398 - INFO - {"message": "Log initialized with Syslog handler. Running on linux2 ", "environment": "PROD", "application": "rbus-sand calculations", "id": "0c13822", "process": "10.0.0.87:", "platform": "python", "severity": "INFO", "version": "unknown", "size": 249}[0m
[34m2018-05-17 10:12:48,342 - rbus-sand calculations - 15398 - INFO - {"message": "Log level set to \"INFO\"", "environment": "PROD", "application": "rbus-sand calculations", "id": "317edaa", "process": "10.0.0.87:", "platform": "python", "severity": "INFO", "version": "unknown", "size": 219}[0m
[34m2018-05-17 10:12:48,345 - rbus-sand calculations - 15398 - INFO - {"message": "Environment set to \"Prod\"", "environment": "PROD", "application": "rbus-sand calculations", "id": "4df4e24", "process": "10.0.0.87:", "platform": "python", "severity": "INFO", "version": "unknown", "size": 221}[0m
[34m2018-05-17 10:12:48,347 - rbus-sand calculations - 15398 - INFO - {"message": "Process PID is 15398", "environment": "PROD", "application": "rbus-sand calculations", "id": "7bdfe5f", "process": "10.0.0.87:", "platform": "python", "severity": "INFO", "version": "unknown", "size": 214}[0m
[34m2018-05-17 10:12:52,992 - rbus-sand calculations - 15398 - INFO - {"message": "Projects data is empty, loading data into memory cache...", "environment": "PROD", "application": "rbus-sand calculations", "id": "083b2d5", "process": "10.0.0.87:", "platform": "python", "severity": "INFO", "version": "unknown", "size": 251}[0m
[45m[1m[30m2018-05-17 10:14:02,694 - rbus-sand calculations - 15398 - CRITICAL - {"message": "Unhandled exception hook caught", "environment": "PROD", "application": "rbus-sand calculations", "id": "46d0185", "process": "10.0.0.87:", "platform": "python", "severity": "CRITICAL", "version": "unknown", "size": 225}
Traceback (most recent call last):
  File "/opt/pycharm-community-2017.3.1/helpers/pydev/pydevd.py", line 1668, in <module>
    main()
  File "/opt/pycharm-community-2017.3.1/helpers/pydev/pydevd.py", line 1662, in main
    globals = debugger.run(setup['file'], None, None, is_module)
  File "/opt/pycharm-community-2017.3.1/helpers/pydev/pydevd.py", line 1072, in run
    pydev_imports.execfile(file, globals, locals)  # execute the script
  File "/home/yoava/dev/trax_ace_factory/Projects/RBUS_SAND/Calculations.py", line 23, in <module>
    data_provider = KEngineDataProvider(project_name)
  File "/home/yoava/miniconda/envs/garage/lib/python2.7/site-packages/Trax/Algo/Calculations/Core/DataProvider.py", line 152, in __init__
    self.orm_session = orm_session if orm_session is not None else OrmSession(project_name, writable=True)
  File "/home/yoava/miniconda/envs/garage/lib/python2.7/site-packages/Trax/Data/Orm/OrmCore.py", line 27, in __init__
    self.session = ProjectsSessions.get_session(project_name, writable, autocommit)
  File "/home/yoava/miniconda/envs/garage/lib/python2.7/site-packages/Trax/Data/Orm/OrmCore.py", line 53, in get_session
    cls.sessions.__setattr__(key_name, InnerOrmSession(project_name, writable, autocommit))
  File "/home/yoava/miniconda/envs/garage/lib/python2.7/site-packages/Trax/Data/Orm/OrmCore.py", line 72, in __init__
    project_instances = ProjectStore.get_project(project_name)
  File "/home/yoava/miniconda/envs/garage/lib/python2.7/site-packages/Trax/Data/Projects/Store.py", line 322, in get_project
    cls._check_invalidation_condition(use_cache)
  File "/home/yoava/miniconda/envs/garage/lib/python2.7/site-packages/Trax/Data/Projects/Store.py", line 99, in _check_invalidation_condition
    cls._load_data()
  File "/home/yoava/miniconda/envs/garage/lib/python2.7/site-packages/Trax/Data/Projects/Store.py", line 54, in _load_data
    conn = MongoConnector(MongoConnector.SMART, use_vault=True)
  File "/home/yoava/miniconda/envs/garage/lib/python2.7/site-packages/Trax/Mongo/Connector.py", line 319, in __init__
    self._get_credentials()
  File "/home/yoava/miniconda/envs/garage/lib/python2.7/site-packages/Trax/Mongo/Connector.py", line 372, in _get_credentials
    self._update_credentials_from_vault()
  File "/home/yoava/miniconda/envs/garage/lib/python2.7/site-packages/Trax/Mongo/Connector.py", line 421, in _update_credentials_from_vault
    user = ResourceUsers.get_user_credentials(resource_field)
  File "/home/yoava/miniconda/envs/garage/lib/python2.7/site-packages/Trax/Cloud/Services/Connector/Keys.py", line 409, in get_user_credentials
    cred = CredentialsFactory.get_credentials(resource, vault_cred_url=vault_cred_url)
  File "/home/yoava/miniconda/envs/garage/lib/python2.7/site-packages/Trax/Cloud/Services/Connector/Factory.py", line 85, in get_credentials
    vault_cred_url = cls.create_vault_cred_url(resource)
  File "/home/yoava/miniconda/envs/garage/lib/python2.7/site-packages/Trax/Cloud/Services/Connector/Factory.py", line 124, in create_vault_cred_url
    if not system_name or system_name.lower() not in cls.get_all_systems():
  File "/home/yoava/miniconda/envs/garage/lib/python2.7/site-packages/Trax/Cloud/Services/Connector/Factory.py", line 23, in get_all_systems
    cls.all_systems = map(lambda system: system.lower(), FilesManager().get_all_python_files())
  File "/home/yoava/miniconda/envs/garage/lib/python2.7/site-packages/Trax/Utils/Classes/System.py", line 19, in get_all_python_files
    all_files = next(os.walk(self.dir_path))[2]
  File "/home/yoava/miniconda/envs/garage/lib/python2.7/site-packages/Trax/Utils/Classes/System.py", line 19, in get_all_python_files
    all_files = next(os.walk(self.dir_path))[2]
  File "_pydevd_bundle/pydevd_cython.pyx", line 968, in _pydevd_bundle.pydevd_cython.SafeCallWrapper.__call__ (_pydevd_bundle/pydevd_cython.c:19675)
    ret = (<object>method_obj)(*args)
  File "_pydevd_bundle/pydevd_cython.pyx", line 515, in _pydevd_bundle.pydevd_cython.PyDBFrame.trace_dispatch (_pydevd_bundle/pydevd_cython.c:19009)
    cpdef trace_dispatch(self, frame, str event, arg):
  File "_pydevd_bundle/pydevd_cython.pyx", line 758, in _pydevd_bundle.pydevd_cython.PyDBFrame.trace_dispatch (_pydevd_bundle/pydevd_cython.c:16066)
    raise
  File "_pydevd_bundle/pydevd_cython.pyx", line 749, in _pydevd_bundle.pydevd_cython.PyDBFrame.trace_dispatch (_pydevd_bundle/pydevd_cython.c:15912)
    self.do_wait_suspend(thread, frame, event, arg)
  File "_pydevd_bundle/pydevd_cython.pyx", line 254, in _pydevd_bundle.pydevd_cython.PyDBFrame.do_wait_suspend (_pydevd_bundle/pydevd_cython.c:5648)
    self._args[0].do_wait_suspend(*args, **kwargs)
  File "/opt/pycharm-community-2017.3.1/helpers/pydev/pydevd.py", line 817, in do_wait_suspend
    time.sleep(0.01)
KeyboardInterrupt[0m
[34m2018-05-17 10:14:22,564 - rbus-sand calculations - 15878 - INFO - {"message": "Log is saved to /home/yoava/dev/trax_ace_factory/Projects/RBUS_SAND/log.txt", "environment": "PROD", "application": "rbus-sand calculations", "cloud": "AWS", "id": "e4f45c9", "process": "10.0.0.87:", "platform": "python", "severity": "INFO", "version": "unknown", "size": 285}[0m
[34m2018-05-17 10:14:23,642 - rbus-sand calculations - 15878 - INFO - {"message": "Log initialized with Syslog handler. Running on linux2 ", "environment": "PROD", "application": "rbus-sand calculations", "cloud": "AWS", "id": "5a0218e", "process": "10.0.0.87:", "platform": "python", "severity": "INFO", "version": "unknown", "size": 265}[0m
[34m2018-05-17 10:14:23,650 - rbus-sand calculations - 15878 - INFO - {"message": "Log level set to \"INFO\"", "environment": "PROD", "application": "rbus-sand calculations", "cloud": "AWS", "id": "cc39983", "process": "10.0.0.87:", "platform": "python", "severity": "INFO", "version": "unknown", "size": 235}[0m
[34m2018-05-17 10:14:23,656 - rbus-sand calculations - 15878 - INFO - {"message": "Environment set to \"Prod\"", "environment": "PROD", "application": "rbus-sand calculations", "cloud": "AWS", "id": "1df03e0", "process": "10.0.0.87:", "platform": "python", "severity": "INFO", "version": "unknown", "size": 237}[0m
[34m2018-05-17 10:14:23,660 - rbus-sand calculations - 15878 - INFO - {"message": "Process PID is 15878", "environment": "PROD", "application": "rbus-sand calculations", "cloud": "AWS", "id": "fff274d", "process": "10.0.0.87:", "platform": "python", "severity": "INFO", "version": "unknown", "size": 230}[0m
[34m2018-05-17 10:15:21,778 - rbus-sand calculations - 15878 - INFO - {"message": "Projects data is empty, loading data into memory cache...", "environment": "PROD", "application": "rbus-sand calculations", "cloud": "AWS", "id": "e08ec6a", "process": "10.0.0.87:", "platform": "python", "severity": "INFO", "version": "unknown", "size": 267}[0m
[34m2018-05-17 10:15:22,734 - rbus-sand calculations - 15878 - INFO - {"message": "get_credentials: get request returned errors: [u'entry for role yoava@TraxRetail.com not found']", "environment": "PROD", "application": "rbus-sand calculations", "cloud": "AWS", "id": "fc56a0b", "process": "10.0.0.87:", "platform": "python", "severity": "INFO", "version": "unknown", "size": 306}[0m
[34m2018-05-17 10:15:23,677 - rbus-sand calculations - 15878 - INFO - {"message": "get_credentials: get request returned errors: [u'entry for role yoava@TraxRetail.com not found']", "environment": "PROD", "application": "rbus-sand calculations", "cloud": "AWS", "id": "fc56a0b", "process": "10.0.0.87:", "platform": "python", "severity": "INFO", "version": "unknown", "size": 306}[0m
[43m[30m2018-05-17 10:15:23,686 - rbus-sand calculations - 15878 - WARNING - {"message": "get_credentials: Failed to retrieve credentials from vault: exception is :Login to vault failed 1 tiems. last login resulted errors: [u'entry for role yoava@TraxRetail.com not found']", "environment": "PROD", "application": "rbus-sand calculations", "cloud": "AWS", "id": "92a0ca6", "process": "10.0.0.87:", "platform": "python", "severity": "WARNING", "version": "unknown", "size": 393}[0m
[43m[30m2018-05-17 10:15:23,693 - rbus-sand calculations - 15878 - WARNING - {"message": "Traceback (most recent call last):\n  File \"/home/yoava/dev/theGarage/Trax/Cloud/Services/Connector/Factory.py\", line 87, in get_credentials\n    token = cls.cloud_adapter.get_vault_token(force)\n  File \"/home/yoava/dev/theGarage/Trax/Cloud/Services/Connector/ConnectorAdapter.py\", line 92, in get_vault_token\n    self._login_vault_request()\n  File \"/home/yoava/dev/theGarage/Trax/Cloud/Services/Connector/ConnectorAdapter.py\", line 68, in _login_vault_request\n    self._check_for_errors(result, retries)\n  File \"/home/yoava/dev/theGarage/Trax/Cloud/Services/Connector/ConnectorAdapter.py\", line 82, in _check_for_errors\n    return self._login_vault_request(retries - 1)\n  File \"/home/yoava/dev/theGarage/Trax/Cloud/Services/Connector/ConnectorAdapter.py\", line 68, in _login_vault_request\n    self._check_for_errors(result, retries)\n  File \"/home/yoava/dev/theGarage/Trax/Cloud/Services/Connector/ConnectorAdapter.py\", line 83, in _check_for_errors\n    raise Exception(VaultRequest.LOGIN_FAILED_ERR.format(VaultResource.RETRY_AMOUNT, errors))\nException: Login to vault failed 1 tiems. last login resulted errors: [u'entry for role yoava@TraxRetail.com not found']\n", "environment": "PROD", "application": "rbus-sand calculations", "cloud": "AWS", "id": "a2d05a8", "process": "10.0.0.87:", "platform": "python", "severity": "WARNING", "version": "unknown", "size": 1398}[0m
[45m[1m[30m2018-05-17 10:15:23,817 - rbus-sand calculations - 15878 - CRITICAL - {"message": "Unhandled exception hook caught", "environment": "PROD", "application": "rbus-sand calculations", "cloud": "AWS", "id": "b947eea", "process": "10.0.0.87:", "platform": "python", "severity": "CRITICAL", "version": "unknown", "size": 241}
Traceback (most recent call last):
  File "/opt/pycharm-community-2017.3.1/helpers/pydev/pydevd.py", line 1668, in <module>
    main()
  File "/opt/pycharm-community-2017.3.1/helpers/pydev/pydevd.py", line 1662, in main
    globals = debugger.run(setup['file'], None, None, is_module)
  File "/opt/pycharm-community-2017.3.1/helpers/pydev/pydevd.py", line 1072, in run
    pydev_imports.execfile(file, globals, locals)  # execute the script
  File "/home/yoava/dev/trax_ace_factory/Projects/RBUS_SAND/Calculations.py", line 23, in <module>
    data_provider = KEngineDataProvider(project_name)
  File "/home/yoava/dev/theGarage/Trax/Algo/Calculations/Core/DataProvider.py", line 152, in __init__
    self.orm_session = orm_session if orm_session is not None else OrmSession(project_name, writable=True)
  File "/home/yoava/dev/theGarage/Trax/Data/Orm/OrmCore.py", line 27, in __init__
    self.session = ProjectsSessions.get_session(project_name, writable, autocommit)
  File "/home/yoava/dev/theGarage/Trax/Data/Orm/OrmCore.py", line 53, in get_session
    cls.sessions.__setattr__(key_name, InnerOrmSession(project_name, writable, autocommit))
  File "/home/yoava/dev/theGarage/Trax/Data/Orm/OrmCore.py", line 72, in __init__
    project_instances = ProjectStore.get_project(project_name)
  File "/home/yoava/dev/theGarage/Trax/Data/Projects/Store.py", line 322, in get_project
    cls._check_invalidation_condition(use_cache)
  File "/home/yoava/dev/theGarage/Trax/Data/Projects/Store.py", line 99, in _check_invalidation_condition
    cls._load_data()
  File "/home/yoava/dev/theGarage/Trax/Data/Projects/Store.py", line 54, in _load_data
    conn = MongoConnector(MongoConnector.SMART, use_vault=True)
  File "/home/yoava/dev/theGarage/Trax/Mongo/Connector.py", line 319, in __init__
    self._get_credentials()
  File "/home/yoava/dev/theGarage/Trax/Mongo/Connector.py", line 378, in _get_credentials
    self._update_credentials_from_secret_keys()
  File "/home/yoava/dev/theGarage/Trax/Mongo/Connector.py", line 405, in _update_credentials_from_secret_keys
    self.username = getattr(secret_keys, username_field)()
  File "/home/yoava/dev/theGarage/Trax/Utils/Conf/Configuration.py", line 418, in mongo_username
    return cls._get_field_by_method_name()
  File "/home/yoava/dev/theGarage/Trax/Utils/Conf/Configuration.py", line 918, in _get_field_by_method_name
    key_name = inspect.stack()[1][3]
  File "/home/yoava/miniconda/envs/garage/lib/python2.7/inspect.py", line 1055, in stack
    return getouterframes(sys._getframe(1), context)
  File "/home/yoava/miniconda/envs/garage/lib/python2.7/inspect.py", line 1033, in getouterframes
    framelist.append((frame,) + getframeinfo(frame, context))
  File "/home/yoava/miniconda/envs/garage/lib/python2.7/inspect.py", line 1008, in getframeinfo
    lines, lnum = findsource(frame)
  File "/home/yoava/miniconda/envs/garage/lib/python2.7/inspect.py", line 532, in findsource
    module = getmodule(object, file)
  File "/home/yoava/miniconda/envs/garage/lib/python2.7/inspect.py", line 500, in getmodule
    os.path.realpath(f)] = module.__name__
  File "/home/yoava/miniconda/envs/garage/lib/python2.7/posixpath.py", line 367, in realpath
    path, ok = _joinrealpath('', filename, {})
  File "/home/yoava/miniconda/envs/garage/lib/python2.7/posixpath.py", line 392, in _joinrealpath
    if not islink(newpath):
  File "/home/yoava/miniconda/envs/garage/lib/python2.7/posixpath.py", line 145, in islink
    return stat.S_ISLNK(st.st_mode)
  File "/home/yoava/miniconda/envs/garage/lib/python2.7/stat.py", line 56, in S_ISLNK
    return S_IFMT(mode) == S_IFLNK
  File "/home/yoava/miniconda/envs/garage/lib/python2.7/stat.py", line 24, in S_IFMT
    def S_IFMT(mode):
KeyboardInterrupt[0m
[34m2018-05-17 10:15:25,680 - rbus-sand calculations - 16170 - INFO - {"message": "Log is saved to /home/yoava/dev/trax_ace_factory/Projects/RBUS_SAND/log.txt", "environment": "PROD", "application": "rbus-sand calculations", "cloud": "AWS", "id": "e4f45c9", "process": "10.0.0.87:", "platform": "python", "severity": "INFO", "version": "unknown", "size": 285}[0m
[34m2018-05-17 10:15:26,743 - rbus-sand calculations - 16170 - INFO - {"message": "Log initialized with Syslog handler. Running on linux2 ", "environment": "PROD", "application": "rbus-sand calculations", "cloud": "AWS", "id": "5a0218e", "process": "10.0.0.87:", "platform": "python", "severity": "INFO", "version": "unknown", "size": 265}[0m
[34m2018-05-17 10:15:26,745 - rbus-sand calculations - 16170 - INFO - {"message": "Log level set to \"INFO\"", "environment": "PROD", "application": "rbus-sand calculations", "cloud": "AWS", "id": "cc39983", "process": "10.0.0.87:", "platform": "python", "severity": "INFO", "version": "unknown", "size": 235}[0m
[34m2018-05-17 10:15:26,748 - rbus-sand calculations - 16170 - INFO - {"message": "Environment set to \"Prod\"", "environment": "PROD", "application": "rbus-sand calculations", "cloud": "AWS", "id": "1df03e0", "process": "10.0.0.87:", "platform": "python", "severity": "INFO", "version": "unknown", "size": 237}[0m
[34m2018-05-17 10:15:26,750 - rbus-sand calculations - 16170 - INFO - {"message": "Process PID is 16170", "environment": "PROD", "application": "rbus-sand calculations", "cloud": "AWS", "id": "fff274d", "process": "10.0.0.87:", "platform": "python", "severity": "INFO", "version": "unknown", "size": 230}[0m
[34m2018-05-17 10:16:17,748 - rbus-sand calculations - 16170 - INFO - {"message": "Projects data is empty, loading data into memory cache...", "environment": "PROD", "application": "rbus-sand calculations", "cloud": "AWS", "id": "e08ec6a", "process": "10.0.0.87:", "platform": "python", "severity": "INFO", "version": "unknown", "size": 267}[0m
[45m[1m[30m2018-05-17 10:22:57,678 - rbus-sand calculations - 16170 - CRITICAL - {"message": "Unhandled exception hook caught", "environment": "PROD", "application": "rbus-sand calculations", "cloud": "AWS", "id": "1bf0493", "process": "10.0.0.87:", "platform": "python", "severity": "CRITICAL", "version": "unknown", "size": 241}
Traceback (most recent call last):
  File "/opt/pycharm-community-2017.3.1/helpers/pydev/pydevd.py", line 1668, in <module>
    main()
  File "/opt/pycharm-community-2017.3.1/helpers/pydev/pydevd.py", line 1662, in main
    globals = debugger.run(setup['file'], None, None, is_module)
  File "/opt/pycharm-community-2017.3.1/helpers/pydev/pydevd.py", line 1072, in run
    pydev_imports.execfile(file, globals, locals)  # execute the script
  File "/home/yoava/dev/trax_ace_factory/Projects/RBUS_SAND/Calculations.py", line 23, in <module>
    data_provider = KEngineDataProvider(project_name)
  File "/home/yoava/dev/theGarage/Trax/Algo/Calculations/Core/DataProvider.py", line 152, in __init__
    self.orm_session = orm_session if orm_session is not None else OrmSession(project_name, writable=True)
  File "/home/yoava/dev/theGarage/Trax/Data/Orm/OrmCore.py", line 27, in __init__
    self.session = ProjectsSessions.get_session(project_name, writable, autocommit)
  File "/home/yoava/dev/theGarage/Trax/Data/Orm/OrmCore.py", line 53, in get_session
    cls.sessions.__setattr__(key_name, InnerOrmSession(project_name, writable, autocommit))
  File "/home/yoava/dev/theGarage/Trax/Data/Orm/OrmCore.py", line 72, in __init__
    project_instances = ProjectStore.get_project(project_name)
  File "/home/yoava/dev/theGarage/Trax/Data/Projects/Store.py", line 322, in get_project
    cls._check_invalidation_condition(use_cache)
  File "/home/yoava/dev/theGarage/Trax/Data/Projects/Store.py", line 99, in _check_invalidation_condition
    cls._load_data()
  File "/home/yoava/dev/theGarage/Trax/Data/Projects/Store.py", line 54, in _load_data
    conn = MongoConnector(MongoConnector.SMART, use_vault=True)
  File "/home/yoava/dev/theGarage/Trax/Mongo/Connector.py", line 319, in __init__
    self._get_credentials()
  File "/home/yoava/dev/theGarage/Trax/Mongo/Connector.py", line 372, in _get_credentials
    self._update_credentials_from_vault()
  File "/home/yoava/dev/theGarage/Trax/Mongo/Connector.py", line 421, in _update_credentials_from_vault
    user = ResourceUsers.get_user_credentials(resource_field)
  File "/home/yoava/dev/theGarage/Trax/Cloud/Services/Connector/Keys.py", line 409, in get_user_credentials
    cred = CredentialsFactory.get_credentials(resource, vault_cred_url=vault_cred_url)
  File "/home/yoava/dev/theGarage/Trax/Cloud/Services/Connector/Factory.py", line 85, in get_credentials
    vault_cred_url = cls.create_vault_cred_url(resource)
  File "/home/yoava/dev/theGarage/Trax/Cloud/Services/Connector/Factory.py", line 124, in create_vault_cred_url
    if not system_name or system_name.lower() not in cls.get_all_systems():
  File "/home/yoava/dev/theGarage/Trax/Cloud/Services/Connector/Factory.py", line 23, in get_all_systems
    cls.all_systems = map(lambda system: system.lower(), FilesManager().get_all_python_files())
  File "/home/yoava/dev/theGarage/Trax/Utils/Classes/System.py", line 20, in get_all_python_files
    return [x.replace(".py", "") for x in all_files if x not in self.files_to_ignore and x[-3:] != "pyc"]
  File "/home/yoava/dev/theGarage/Trax/Utils/Classes/System.py", line 20, in get_all_python_files
    return [x.replace(".py", "") for x in all_files if x not in self.files_to_ignore and x[-3:] != "pyc"]
  File "/opt/pycharm-community-2017.3.1/helpers/pydev/_pydevd_bundle/pydevd_trace_dispatch.py", line 55, in trace_dispatch
    return _trace_dispatch(py_db, frame, event, arg)
  File "_pydevd_bundle/pydevd_cython.pyx", line 955, in _pydevd_bundle.pydevd_cython.trace_dispatch (_pydevd_bundle/pydevd_cython.c:19489)
    return thread_tracer.__call__(frame, event, arg)
  File "_pydevd_bundle/pydevd_cython.pyx", line 1076, in _pydevd_bundle.pydevd_cython.ThreadTracer.__call__ (_pydevd_bundle/pydevd_cython.c:21396)
    (frame.f_code.co_name, frame.f_code.co_firstlineno, filename))).trace_dispatch(frame,
  File "_pydevd_bundle/pydevd_cython.pyx", line 758, in _pydevd_bundle.pydevd_cython.PyDBFrame.trace_dispatch (_pydevd_bundle/pydevd_cython.c:16066)
    raise
  File "_pydevd_bundle/pydevd_cython.pyx", line 749, in _pydevd_bundle.pydevd_cython.PyDBFrame.trace_dispatch (_pydevd_bundle/pydevd_cython.c:15912)
    self.do_wait_suspend(thread, frame, event, arg)
  File "_pydevd_bundle/pydevd_cython.pyx", line 254, in _pydevd_bundle.pydevd_cython.PyDBFrame.do_wait_suspend (_pydevd_bundle/pydevd_cython.c:5648)
    self._args[0].do_wait_suspend(*args, **kwargs)
  File "/opt/pycharm-community-2017.3.1/helpers/pydev/pydevd.py", line 817, in do_wait_suspend
    time.sleep(0.01)
KeyboardInterrupt[0m
[34m2018-05-17 10:23:17,162 - rbus-sand calculations - 17296 - INFO - {"message": "Log is saved to /home/yoava/dev/trax_ace_factory/Projects/RBUS_SAND/log.txt", "environment": "PROD", "application": "rbus-sand calculations", "id": "ea03a0c", "process": "10.0.0.87:", "platform": "python", "severity": "INFO", "version": "unknown", "size": 269}[0m
[34m2018-05-17 10:23:18,213 - rbus-sand calculations - 17296 - INFO - {"message": "Log initialized with Syslog handler. Running on linux2 ", "environment": "PROD", "application": "rbus-sand calculations", "id": "0c13822", "process": "10.0.0.87:", "platform": "python", "severity": "INFO", "version": "unknown", "size": 249}[0m
[34m2018-05-17 10:23:18,214 - rbus-sand calculations - 17296 - INFO - {"message": "Log level set to \"INFO\"", "environment": "PROD", "application": "rbus-sand calculations", "id": "317edaa", "process": "10.0.0.87:", "platform": "python", "severity": "INFO", "version": "unknown", "size": 219}[0m
[34m2018-05-17 10:23:18,216 - rbus-sand calculations - 17296 - INFO - {"message": "Environment set to \"Prod\"", "environment": "PROD", "application": "rbus-sand calculations", "id": "4df4e24", "process": "10.0.0.87:", "platform": "python", "severity": "INFO", "version": "unknown", "size": 221}[0m
[34m2018-05-17 10:23:18,218 - rbus-sand calculations - 17296 - INFO - {"message": "Process PID is 17296", "environment": "PROD", "application": "rbus-sand calculations", "id": "7bdfe5f", "process": "10.0.0.87:", "platform": "python", "severity": "INFO", "version": "unknown", "size": 214}[0m
[34m2018-05-17 10:23:18,446 - rbus-sand calculations - 17296 - INFO - {"message": "Projects data is empty, loading data into memory cache...", "environment": "PROD", "application": "rbus-sand calculations", "id": "083b2d5", "process": "10.0.0.87:", "platform": "python", "severity": "INFO", "version": "unknown", "size": 251}[0m
[31m[1m2018-05-17 10:23:18,448 - rbus-sand calculations - 17296 - ERROR - {
    "message": "Exception unhandled was caught. Exception is : ",
    "environment": "PROD",
    "application": "rbus-sand calculations",
    "id": "de3406b",
    "process": "10.0.0.87:",
    "platform": "python",
    "severity": "ERROR",
    "version": "unknown",
    "traceback": [
        "Traceback (most recent call last):",
        "  File \"/home/yoava/miniconda/envs/garage/lib/python2.7/site-packages/Trax/Utils/Classes/System.py\", line 19, in get_all_python_files",
        "    all_files = next(os.walk(self.dir_path))[2]",
        "StopIteration"
    ],
    "size": 577
}[0m
[45m[1m[30m2018-05-17 10:23:18,818 - rbus-sand calculations - 17296 - CRITICAL - {"message": "Unhandled exception hook caught", "environment": "PROD", "application": "rbus-sand calculations", "id": "70e5dca", "process": "10.0.0.87:", "platform": "python", "severity": "CRITICAL", "version": "unknown", "size": 225}
Traceback (most recent call last):
  File "/home/yoava/dev/trax_ace_factory/Projects/RBUS_SAND/Calculations.py", line 23, in <module>
    data_provider = KEngineDataProvider(project_name)
  File "/home/yoava/miniconda/envs/garage/lib/python2.7/site-packages/Trax/Algo/Calculations/Core/DataProvider.py", line 152, in __init__
    self.orm_session = orm_session if orm_session is not None else OrmSession(project_name, writable=True)
  File "/home/yoava/miniconda/envs/garage/lib/python2.7/site-packages/Trax/Data/Orm/OrmCore.py", line 27, in __init__
    self.session = ProjectsSessions.get_session(project_name, writable, autocommit)
  File "/home/yoava/miniconda/envs/garage/lib/python2.7/site-packages/Trax/Data/Orm/OrmCore.py", line 53, in get_session
    cls.sessions.__setattr__(key_name, InnerOrmSession(project_name, writable, autocommit))
  File "/home/yoava/miniconda/envs/garage/lib/python2.7/site-packages/Trax/Data/Orm/OrmCore.py", line 72, in __init__
    project_instances = ProjectStore.get_project(project_name)
  File "/home/yoava/miniconda/envs/garage/lib/python2.7/site-packages/Trax/Data/Projects/Store.py", line 322, in get_project
    cls._check_invalidation_condition(use_cache)
  File "/home/yoava/miniconda/envs/garage/lib/python2.7/site-packages/Trax/Data/Projects/Store.py", line 99, in _check_invalidation_condition
    cls._load_data()
  File "/home/yoava/miniconda/envs/garage/lib/python2.7/site-packages/Trax/Data/Projects/Store.py", line 54, in _load_data
    conn = MongoConnector(MongoConnector.SMART, use_vault=True)
  File "/home/yoava/miniconda/envs/garage/lib/python2.7/site-packages/Trax/Mongo/Connector.py", line 319, in __init__
    self._get_credentials()
  File "/home/yoava/miniconda/envs/garage/lib/python2.7/site-packages/Trax/Mongo/Connector.py", line 372, in _get_credentials
    self._update_credentials_from_vault()
  File "/home/yoava/miniconda/envs/garage/lib/python2.7/site-packages/Trax/Mongo/Connector.py", line 421, in _update_credentials_from_vault
    user = ResourceUsers.get_user_credentials(resource_field)
  File "/home/yoava/miniconda/envs/garage/lib/python2.7/site-packages/Trax/Cloud/Services/Connector/Keys.py", line 409, in get_user_credentials
    cred = CredentialsFactory.get_credentials(resource, vault_cred_url=vault_cred_url)
  File "/home/yoava/miniconda/envs/garage/lib/python2.7/site-packages/Trax/Cloud/Services/Connector/Factory.py", line 87, in get_credentials
    token = cls.cloud_adapter.get_vault_token(force)
  File "/home/yoava/miniconda/envs/garage/lib/python2.7/site-packages/Trax/Cloud/Services/Connector/ConnectorAdapter.py", line 92, in get_vault_token
    self._login_vault_request()
  File "/home/yoava/miniconda/envs/garage/lib/python2.7/site-packages/Trax/Cloud/Services/Connector/ConnectorAdapter.py", line 67, in _login_vault_request
    result = json.loads(requests.post(url=self.login_vault_url, data=data, timeout=VAULT_TOKEN_REQUEST_TIMEOUT).text)
  File "/home/yoava/miniconda/envs/garage/lib/python2.7/site-packages/requests/api.py", line 112, in post
    return request('post', url, data=data, json=json, **kwargs)
  File "/home/yoava/miniconda/envs/garage/lib/python2.7/site-packages/requests/api.py", line 58, in request
    return session.request(method=method, url=url, **kwargs)
  File "/home/yoava/miniconda/envs/garage/lib/python2.7/site-packages/requests/sessions.py", line 502, in request
    resp = self.send(prep, **send_kwargs)
  File "/home/yoava/miniconda/envs/garage/lib/python2.7/site-packages/requests/sessions.py", line 612, in send
    r = adapter.send(request, **kwargs)
  File "/home/yoava/miniconda/envs/garage/lib/python2.7/site-packages/requests/adapters.py", line 440, in send
    timeout=timeout
  File "/home/yoava/miniconda/envs/garage/lib/python2.7/site-packages/urllib3/connectionpool.py", line 600, in urlopen
    chunked=chunked)
  File "/home/yoava/miniconda/envs/garage/lib/python2.7/site-packages/urllib3/connectionpool.py", line 345, in _make_request
    self._validate_conn(conn)
  File "/home/yoava/miniconda/envs/garage/lib/python2.7/site-packages/urllib3/connectionpool.py", line 844, in _validate_conn
    conn.connect()
  File "/home/yoava/miniconda/envs/garage/lib/python2.7/site-packages/urllib3/connection.py", line 284, in connect
    conn = self._new_conn()
  File "/home/yoava/miniconda/envs/garage/lib/python2.7/site-packages/urllib3/connection.py", line 141, in _new_conn
    (self.host, self.port), self.timeout, **extra_kw)
  File "/home/yoava/miniconda/envs/garage/lib/python2.7/site-packages/urllib3/util/connection.py", line 73, in create_connection
    sock.connect(sa)
  File "/home/yoava/miniconda/envs/garage/lib/python2.7/socket.py", line 224, in meth
    return getattr(self._sock,name)(*args)
KeyboardInterrupt[0m
[34m2018-05-17 10:23:22,263 - rbus-sand calculations - 17325 - INFO - {"message": "Log is saved to /home/yoava/dev/trax_ace_factory/Projects/RBUS_SAND/log.txt", "environment": "PROD", "application": "rbus-sand calculations", "id": "ea03a0c", "process": "10.0.0.87:", "platform": "python", "severity": "INFO", "version": "unknown", "size": 269}[0m
[34m2018-05-17 10:23:23,288 - rbus-sand calculations - 17325 - INFO - {"message": "Log initialized with Syslog handler. Running on linux2 ", "environment": "PROD", "application": "rbus-sand calculations", "id": "0c13822", "process": "10.0.0.87:", "platform": "python", "severity": "INFO", "version": "unknown", "size": 249}[0m
[34m2018-05-17 10:23:23,289 - rbus-sand calculations - 17325 - INFO - {"message": "Log level set to \"INFO\"", "environment": "PROD", "application": "rbus-sand calculations", "id": "317edaa", "process": "10.0.0.87:", "platform": "python", "severity": "INFO", "version": "unknown", "size": 219}[0m
[34m2018-05-17 10:23:23,290 - rbus-sand calculations - 17325 - INFO - {"message": "Environment set to \"Prod\"", "environment": "PROD", "application": "rbus-sand calculations", "id": "4df4e24", "process": "10.0.0.87:", "platform": "python", "severity": "INFO", "version": "unknown", "size": 221}[0m
[34m2018-05-17 10:23:23,292 - rbus-sand calculations - 17325 - INFO - {"message": "Process PID is 17325", "environment": "PROD", "application": "rbus-sand calculations", "id": "7bdfe5f", "process": "10.0.0.87:", "platform": "python", "severity": "INFO", "version": "unknown", "size": 214}[0m
[34m2018-05-17 10:23:27,138 - rbus-sand calculations - 17325 - INFO - {"message": "Projects data is empty, loading data into memory cache...", "environment": "PROD", "application": "rbus-sand calculations", "id": "083b2d5", "process": "10.0.0.87:", "platform": "python", "severity": "INFO", "version": "unknown", "size": 251}[0m
[45m[1m[30m2018-05-17 10:27:40,730 - rbus-sand calculations - 17325 - CRITICAL - {"message": "Unhandled exception hook caught", "environment": "PROD", "application": "rbus-sand calculations", "id": "46d0185", "process": "10.0.0.87:", "platform": "python", "severity": "CRITICAL", "version": "unknown", "size": 225}
Traceback (most recent call last):
  File "/opt/pycharm-community-2017.3.1/helpers/pydev/pydevd.py", line 1668, in <module>
    main()
  File "/opt/pycharm-community-2017.3.1/helpers/pydev/pydevd.py", line 1662, in main
    globals = debugger.run(setup['file'], None, None, is_module)
  File "/opt/pycharm-community-2017.3.1/helpers/pydev/pydevd.py", line 1072, in run
    pydev_imports.execfile(file, globals, locals)  # execute the script
  File "/home/yoava/dev/trax_ace_factory/Projects/RBUS_SAND/Calculations.py", line 23, in <module>
    data_provider = KEngineDataProvider(project_name)
  File "/home/yoava/miniconda/envs/garage/lib/python2.7/site-packages/Trax/Algo/Calculations/Core/DataProvider.py", line 152, in __init__
    self.orm_session = orm_session if orm_session is not None else OrmSession(project_name, writable=True)
  File "/home/yoava/miniconda/envs/garage/lib/python2.7/site-packages/Trax/Data/Orm/OrmCore.py", line 27, in __init__
    self.session = ProjectsSessions.get_session(project_name, writable, autocommit)
  File "/home/yoava/miniconda/envs/garage/lib/python2.7/site-packages/Trax/Data/Orm/OrmCore.py", line 53, in get_session
    cls.sessions.__setattr__(key_name, InnerOrmSession(project_name, writable, autocommit))
  File "/home/yoava/miniconda/envs/garage/lib/python2.7/site-packages/Trax/Data/Orm/OrmCore.py", line 72, in __init__
    project_instances = ProjectStore.get_project(project_name)
  File "/home/yoava/miniconda/envs/garage/lib/python2.7/site-packages/Trax/Data/Projects/Store.py", line 322, in get_project
    cls._check_invalidation_condition(use_cache)
  File "/home/yoava/miniconda/envs/garage/lib/python2.7/site-packages/Trax/Data/Projects/Store.py", line 99, in _check_invalidation_condition
    cls._load_data()
  File "/home/yoava/miniconda/envs/garage/lib/python2.7/site-packages/Trax/Data/Projects/Store.py", line 54, in _load_data
    conn = MongoConnector(MongoConnector.SMART, use_vault=True)
  File "/home/yoava/miniconda/envs/garage/lib/python2.7/site-packages/Trax/Mongo/Connector.py", line 319, in __init__
    self._get_credentials()
  File "/home/yoava/miniconda/envs/garage/lib/python2.7/site-packages/Trax/Mongo/Connector.py", line 372, in _get_credentials
    self._update_credentials_from_vault()
  File "/home/yoava/miniconda/envs/garage/lib/python2.7/site-packages/Trax/Mongo/Connector.py", line 421, in _update_credentials_from_vault
    user = ResourceUsers.get_user_credentials(resource_field)
  File "/home/yoava/miniconda/envs/garage/lib/python2.7/site-packages/Trax/Cloud/Services/Connector/Keys.py", line 409, in get_user_credentials
    cred = CredentialsFactory.get_credentials(resource, vault_cred_url=vault_cred_url)
  File "/home/yoava/miniconda/envs/garage/lib/python2.7/site-packages/Trax/Cloud/Services/Connector/Factory.py", line 85, in get_credentials
    vault_cred_url = cls.create_vault_cred_url(resource)
  File "/home/yoava/miniconda/envs/garage/lib/python2.7/site-packages/Trax/Cloud/Services/Connector/Factory.py", line 124, in create_vault_cred_url
    if not system_name or system_name.lower() not in cls.get_all_systems():
  File "/home/yoava/miniconda/envs/garage/lib/python2.7/site-packages/Trax/Cloud/Services/Connector/Factory.py", line 23, in get_all_systems
    cls.all_systems = map(lambda system: system.lower(), FilesManager().get_all_python_files())
  File "/home/yoava/miniconda/envs/garage/lib/python2.7/site-packages/Trax/Utils/Classes/System.py", line 19, in get_all_python_files
    all_files = next(os.walk(self.dir_path))[2]
  File "/home/yoava/miniconda/envs/garage/lib/python2.7/site-packages/Trax/Utils/Classes/System.py", line 19, in get_all_python_files
    all_files = next(os.walk(self.dir_path))[2]
  File "_pydevd_bundle/pydevd_cython.pyx", line 968, in _pydevd_bundle.pydevd_cython.SafeCallWrapper.__call__ (_pydevd_bundle/pydevd_cython.c:19675)
    ret = (<object>method_obj)(*args)
  File "_pydevd_bundle/pydevd_cython.pyx", line 515, in _pydevd_bundle.pydevd_cython.PyDBFrame.trace_dispatch (_pydevd_bundle/pydevd_cython.c:19009)
    cpdef trace_dispatch(self, frame, str event, arg):
  File "_pydevd_bundle/pydevd_cython.pyx", line 758, in _pydevd_bundle.pydevd_cython.PyDBFrame.trace_dispatch (_pydevd_bundle/pydevd_cython.c:16066)
    raise
  File "_pydevd_bundle/pydevd_cython.pyx", line 749, in _pydevd_bundle.pydevd_cython.PyDBFrame.trace_dispatch (_pydevd_bundle/pydevd_cython.c:15912)
    self.do_wait_suspend(thread, frame, event, arg)
  File "_pydevd_bundle/pydevd_cython.pyx", line 254, in _pydevd_bundle.pydevd_cython.PyDBFrame.do_wait_suspend (_pydevd_bundle/pydevd_cython.c:5648)
    self._args[0].do_wait_suspend(*args, **kwargs)
  File "/opt/pycharm-community-2017.3.1/helpers/pydev/pydevd.py", line 817, in do_wait_suspend
    time.sleep(0.01)
KeyboardInterrupt[0m
[34m2018-05-17 10:27:44,148 - rbus-sand calculations - 17759 - INFO - {"message": "Log is saved to /home/yoava/dev/trax_ace_factory/Projects/RBUS_SAND/log.txt", "environment": "PROD", "application": "rbus-sand calculations", "id": "ea03a0c", "process": "10.0.0.87:", "platform": "python", "severity": "INFO", "version": "unknown", "size": 269}[0m
[34m2018-05-17 10:27:45,196 - rbus-sand calculations - 17759 - INFO - {"message": "Log initialized with Syslog handler. Running on linux2 ", "environment": "PROD", "application": "rbus-sand calculations", "id": "0c13822", "process": "10.0.0.87:", "platform": "python", "severity": "INFO", "version": "unknown", "size": 249}[0m
[34m2018-05-17 10:27:45,199 - rbus-sand calculations - 17759 - INFO - {"message": "Log level set to \"INFO\"", "environment": "PROD", "application": "rbus-sand calculations", "id": "317edaa", "process": "10.0.0.87:", "platform": "python", "severity": "INFO", "version": "unknown", "size": 219}[0m
[34m2018-05-17 10:27:45,202 - rbus-sand calculations - 17759 - INFO - {"message": "Environment set to \"Prod\"", "environment": "PROD", "application": "rbus-sand calculations", "id": "4df4e24", "process": "10.0.0.87:", "platform": "python", "severity": "INFO", "version": "unknown", "size": 221}[0m
[34m2018-05-17 10:27:45,205 - rbus-sand calculations - 17759 - INFO - {"message": "Process PID is 17759", "environment": "PROD", "application": "rbus-sand calculations", "id": "7bdfe5f", "process": "10.0.0.87:", "platform": "python", "severity": "INFO", "version": "unknown", "size": 214}[0m
[34m2018-05-17 10:27:45,428 - rbus-sand calculations - 17759 - INFO - {"message": "Projects data is empty, loading data into memory cache...", "environment": "PROD", "application": "rbus-sand calculations", "id": "083b2d5", "process": "10.0.0.87:", "platform": "python", "severity": "INFO", "version": "unknown", "size": 251}[0m
[31m[1m2018-05-17 10:27:45,430 - rbus-sand calculations - 17759 - ERROR - {
    "message": "Exception unhandled was caught. Exception is : ",
    "environment": "PROD",
    "application": "rbus-sand calculations",
    "id": "de3406b",
    "process": "10.0.0.87:",
    "platform": "python",
    "severity": "ERROR",
    "version": "unknown",
    "traceback": [
        "Traceback (most recent call last):",
        "  File \"/home/yoava/miniconda/envs/garage/lib/python2.7/site-packages/Trax/Utils/Classes/System.py\", line 19, in get_all_python_files",
        "    all_files = next(os.walk(self.dir_path))[2]",
        "StopIteration"
    ],
    "size": 577
}[0m
[34m2018-05-17 10:27:46,318 - rbus-sand calculations - 17759 - INFO - {"message": "get_credentials: get request returned errors: [u'entry for role yoava@TraxRetail.com not found']", "environment": "PROD", "application": "rbus-sand calculations", "id": "d658487", "process": "10.0.0.87:", "platform": "python", "severity": "INFO", "version": "unknown", "size": 290}[0m
[34m2018-05-17 10:27:47,190 - rbus-sand calculations - 17759 - INFO - {"message": "get_credentials: get request returned errors: [u'entry for role yoava@TraxRetail.com not found']", "environment": "PROD", "application": "rbus-sand calculations", "id": "d658487", "process": "10.0.0.87:", "platform": "python", "severity": "INFO", "version": "unknown", "size": 290}[0m
[43m[30m2018-05-17 10:27:47,195 - rbus-sand calculations - 17759 - WARNING - {"message": "get_credentials: Failed to retrieve credentials from vault: exception is :Login to vault failed 1 tiems. last login resulted errors: [u'entry for role yoava@TraxRetail.com not found']", "environment": "PROD", "application": "rbus-sand calculations", "id": "5d4a35b", "process": "10.0.0.87:", "platform": "python", "severity": "WARNING", "version": "unknown", "size": 377}[0m
[43m[30m2018-05-17 10:27:47,200 - rbus-sand calculations - 17759 - WARNING - {"message": "Traceback (most recent call last):\n  File \"/home/yoava/miniconda/envs/garage/lib/python2.7/site-packages/Trax/Cloud/Services/Connector/Factory.py\", line 87, in get_credentials\n    token = cls.cloud_adapter.get_vault_token(force)\n  File \"/home/yoava/miniconda/envs/garage/lib/python2.7/site-packages/Trax/Cloud/Services/Connector/ConnectorAdapter.py\", line 92, in get_vault_token\n    self._login_vault_request()\n  File \"/home/yoava/miniconda/envs/garage/lib/python2.7/site-packages/Trax/Cloud/Services/Connector/ConnectorAdapter.py\", line 68, in _login_vault_request\n    self._check_for_errors(result, retries)\n  File \"/home/yoava/miniconda/envs/garage/lib/python2.7/site-packages/Trax/Cloud/Services/Connector/ConnectorAdapter.py\", line 82, in _check_for_errors\n    return self._login_vault_request(retries - 1)\n  File \"/home/yoava/miniconda/envs/garage/lib/python2.7/site-packages/Trax/Cloud/Services/Connector/ConnectorAdapter.py\", line 68, in _login_vault_request\n    self._check_for_errors(result, retries)\n  File \"/home/yoava/miniconda/envs/garage/lib/python2.7/site-packages/Trax/Cloud/Services/Connector/ConnectorAdapter.py\", line 83, in _check_for_errors\n    raise Exception(VaultRequest.LOGIN_FAILED_ERR.format(VaultResource.RETRY_AMOUNT, errors))\nException: Login to vault failed 1 tiems. last login resulted errors: [u'entry for role yoava@TraxRetail.com not found']\n", "environment": "PROD", "application": "rbus-sand calculations", "id": "441af55", "process": "10.0.0.87:", "platform": "python", "severity": "WARNING", "version": "unknown", "size": 1598}[0m
[34m2018-05-17 10:27:51,603 - rbus-sand calculations - 17759 - INFO - {"message": "Loaded projects data into memory cache", "environment": "PROD", "application": "rbus-sand calculations", "id": "659292d", "process": "10.0.0.87:", "platform": "python", "severity": "INFO", "version": "unknown", "size": 232}[0m
[34m2018-05-17 10:27:52,450 - rbus-sand calculations - 17759 - INFO - {"message": "get_credentials: get request returned errors: [u'entry for role yoava@TraxRetail.com not found']", "environment": "PROD", "application": "rbus-sand calculations", "id": "d658487", "process": "10.0.0.87:", "platform": "python", "severity": "INFO", "version": "unknown", "size": 290}[0m
[34m2018-05-17 10:27:53,321 - rbus-sand calculations - 17759 - INFO - {"message": "get_credentials: get request returned errors: [u'entry for role yoava@TraxRetail.com not found']", "environment": "PROD", "application": "rbus-sand calculations", "id": "d658487", "process": "10.0.0.87:", "platform": "python", "severity": "INFO", "version": "unknown", "size": 290}[0m
[43m[30m2018-05-17 10:27:53,324 - rbus-sand calculations - 17759 - WARNING - {"message": "get_credentials: Failed to retrieve credentials from vault: exception is :Login to vault failed 1 tiems. last login resulted errors: [u'entry for role yoava@TraxRetail.com not found']", "environment": "PROD", "application": "rbus-sand calculations", "id": "5d4a35b", "process": "10.0.0.87:", "platform": "python", "severity": "WARNING", "version": "unknown", "size": 377}[0m
[43m[30m2018-05-17 10:27:53,328 - rbus-sand calculations - 17759 - WARNING - {"message": "Traceback (most recent call last):\n  File \"/home/yoava/miniconda/envs/garage/lib/python2.7/site-packages/Trax/Cloud/Services/Connector/Factory.py\", line 87, in get_credentials\n    token = cls.cloud_adapter.get_vault_token(force)\n  File \"/home/yoava/miniconda/envs/garage/lib/python2.7/site-packages/Trax/Cloud/Services/Connector/ConnectorAdapter.py\", line 92, in get_vault_token\n    self._login_vault_request()\n  File \"/home/yoava/miniconda/envs/garage/lib/python2.7/site-packages/Trax/Cloud/Services/Connector/ConnectorAdapter.py\", line 68, in _login_vault_request\n    self._check_for_errors(result, retries)\n  File \"/home/yoava/miniconda/envs/garage/lib/python2.7/site-packages/Trax/Cloud/Services/Connector/ConnectorAdapter.py\", line 82, in _check_for_errors\n    return self._login_vault_request(retries - 1)\n  File \"/home/yoava/miniconda/envs/garage/lib/python2.7/site-packages/Trax/Cloud/Services/Connector/ConnectorAdapter.py\", line 68, in _login_vault_request\n    self._check_for_errors(result, retries)\n  File \"/home/yoava/miniconda/envs/garage/lib/python2.7/site-packages/Trax/Cloud/Services/Connector/ConnectorAdapter.py\", line 83, in _check_for_errors\n    raise Exception(VaultRequest.LOGIN_FAILED_ERR.format(VaultResource.RETRY_AMOUNT, errors))\nException: Login to vault failed 1 tiems. last login resulted errors: [u'entry for role yoava@TraxRetail.com not found']\n", "environment": "PROD", "application": "rbus-sand calculations", "id": "441af55", "process": "10.0.0.87:", "platform": "python", "severity": "WARNING", "version": "unknown", "size": 1598}[0m
[34m2018-05-17 10:28:23,857 - rbus-sand calculations - 17830 - INFO - {"message": "Log is saved to /home/yoava/dev/trax_ace_factory/Projects/RBUS_SAND/log.txt", "environment": "PROD", "application": "rbus-sand calculations", "id": "ea03a0c", "process": "10.0.0.87:", "platform": "python", "severity": "INFO", "version": "unknown", "size": 269}[0m
[34m2018-05-17 10:28:24,924 - rbus-sand calculations - 17830 - INFO - {"message": "Log initialized with Syslog handler. Running on linux2 ", "environment": "PROD", "application": "rbus-sand calculations", "id": "0c13822", "process": "10.0.0.87:", "platform": "python", "severity": "INFO", "version": "unknown", "size": 249}[0m
[34m2018-05-17 10:28:24,927 - rbus-sand calculations - 17830 - INFO - {"message": "Log level set to \"INFO\"", "environment": "PROD", "application": "rbus-sand calculations", "id": "317edaa", "process": "10.0.0.87:", "platform": "python", "severity": "INFO", "version": "unknown", "size": 219}[0m
[34m2018-05-17 10:28:24,929 - rbus-sand calculations - 17830 - INFO - {"message": "Environment set to \"Prod\"", "environment": "PROD", "application": "rbus-sand calculations", "id": "4df4e24", "process": "10.0.0.87:", "platform": "python", "severity": "INFO", "version": "unknown", "size": 221}[0m
[34m2018-05-17 10:28:24,932 - rbus-sand calculations - 17830 - INFO - {"message": "Process PID is 17830", "environment": "PROD", "application": "rbus-sand calculations", "id": "7bdfe5f", "process": "10.0.0.87:", "platform": "python", "severity": "INFO", "version": "unknown", "size": 214}[0m
[34m2018-05-17 10:28:27,378 - rbus-sand calculations - 17830 - INFO - {"message": "Projects data is empty, loading data into memory cache...", "environment": "PROD", "application": "rbus-sand calculations", "id": "083b2d5", "process": "10.0.0.87:", "platform": "python", "severity": "INFO", "version": "unknown", "size": 251}[0m
[45m[1m[30m2018-05-17 10:30:17,164 - rbus-sand calculations - 17830 - CRITICAL - {"message": "Unhandled exception hook caught", "environment": "PROD", "application": "rbus-sand calculations", "id": "46d0185", "process": "10.0.0.87:", "platform": "python", "severity": "CRITICAL", "version": "unknown", "size": 225}
Traceback (most recent call last):
  File "/opt/pycharm-community-2017.3.1/helpers/pydev/pydevd.py", line 1668, in <module>
    main()
  File "/opt/pycharm-community-2017.3.1/helpers/pydev/pydevd.py", line 1662, in main
    globals = debugger.run(setup['file'], None, None, is_module)
  File "/opt/pycharm-community-2017.3.1/helpers/pydev/pydevd.py", line 1072, in run
    pydev_imports.execfile(file, globals, locals)  # execute the script
  File "/home/yoava/dev/trax_ace_factory/Projects/RBUS_SAND/Calculations.py", line 23, in <module>
    data_provider = KEngineDataProvider(project_name)
  File "/home/yoava/miniconda/envs/garage/lib/python2.7/site-packages/Trax/Algo/Calculations/Core/DataProvider.py", line 152, in __init__
    self.orm_session = orm_session if orm_session is not None else OrmSession(project_name, writable=True)
  File "/home/yoava/miniconda/envs/garage/lib/python2.7/site-packages/Trax/Data/Orm/OrmCore.py", line 27, in __init__
    self.session = ProjectsSessions.get_session(project_name, writable, autocommit)
  File "/home/yoava/miniconda/envs/garage/lib/python2.7/site-packages/Trax/Data/Orm/OrmCore.py", line 53, in get_session
    cls.sessions.__setattr__(key_name, InnerOrmSession(project_name, writable, autocommit))
  File "/home/yoava/miniconda/envs/garage/lib/python2.7/site-packages/Trax/Data/Orm/OrmCore.py", line 72, in __init__
    project_instances = ProjectStore.get_project(project_name)
  File "/home/yoava/miniconda/envs/garage/lib/python2.7/site-packages/Trax/Data/Projects/Store.py", line 322, in get_project
    cls._check_invalidation_condition(use_cache)
  File "/home/yoava/miniconda/envs/garage/lib/python2.7/site-packages/Trax/Data/Projects/Store.py", line 99, in _check_invalidation_condition
    cls._load_data()
  File "/home/yoava/miniconda/envs/garage/lib/python2.7/site-packages/Trax/Data/Projects/Store.py", line 54, in _load_data
    conn = MongoConnector(MongoConnector.SMART, use_vault=True)
  File "/home/yoava/miniconda/envs/garage/lib/python2.7/site-packages/Trax/Mongo/Connector.py", line 319, in __init__
    self._get_credentials()
  File "/home/yoava/miniconda/envs/garage/lib/python2.7/site-packages/Trax/Mongo/Connector.py", line 372, in _get_credentials
    self._update_credentials_from_vault()
  File "/home/yoava/miniconda/envs/garage/lib/python2.7/site-packages/Trax/Mongo/Connector.py", line 421, in _update_credentials_from_vault
    user = ResourceUsers.get_user_credentials(resource_field)
  File "/home/yoava/miniconda/envs/garage/lib/python2.7/site-packages/Trax/Cloud/Services/Connector/Keys.py", line 409, in get_user_credentials
    cred = CredentialsFactory.get_credentials(resource, vault_cred_url=vault_cred_url)
  File "/home/yoava/miniconda/envs/garage/lib/python2.7/site-packages/Trax/Cloud/Services/Connector/Factory.py", line 85, in get_credentials
    vault_cred_url = cls.create_vault_cred_url(resource)
  File "/home/yoava/miniconda/envs/garage/lib/python2.7/site-packages/Trax/Cloud/Services/Connector/Factory.py", line 124, in create_vault_cred_url
    if not system_name or system_name.lower() not in cls.get_all_systems():
  File "/home/yoava/miniconda/envs/garage/lib/python2.7/site-packages/Trax/Cloud/Services/Connector/Factory.py", line 23, in get_all_systems
    cls.all_systems = map(lambda system: system.lower(), FilesManager().get_all_python_files())
  File "/home/yoava/miniconda/envs/garage/lib/python2.7/site-packages/Trax/Utils/Classes/System.py", line 19, in get_all_python_files
    all_files = next(os.walk(self.dir_path))[2]
  File "/home/yoava/miniconda/envs/garage/lib/python2.7/site-packages/Trax/Utils/Classes/System.py", line 19, in get_all_python_files
    all_files = next(os.walk(self.dir_path))[2]
  File "_pydevd_bundle/pydevd_cython.pyx", line 968, in _pydevd_bundle.pydevd_cython.SafeCallWrapper.__call__ (_pydevd_bundle/pydevd_cython.c:19675)
    ret = (<object>method_obj)(*args)
  File "_pydevd_bundle/pydevd_cython.pyx", line 515, in _pydevd_bundle.pydevd_cython.PyDBFrame.trace_dispatch (_pydevd_bundle/pydevd_cython.c:19009)
    cpdef trace_dispatch(self, frame, str event, arg):
  File "_pydevd_bundle/pydevd_cython.pyx", line 758, in _pydevd_bundle.pydevd_cython.PyDBFrame.trace_dispatch (_pydevd_bundle/pydevd_cython.c:16066)
    raise
  File "_pydevd_bundle/pydevd_cython.pyx", line 749, in _pydevd_bundle.pydevd_cython.PyDBFrame.trace_dispatch (_pydevd_bundle/pydevd_cython.c:15912)
    self.do_wait_suspend(thread, frame, event, arg)
  File "_pydevd_bundle/pydevd_cython.pyx", line 254, in _pydevd_bundle.pydevd_cython.PyDBFrame.do_wait_suspend (_pydevd_bundle/pydevd_cython.c:5648)
    self._args[0].do_wait_suspend(*args, **kwargs)
  File "/opt/pycharm-community-2017.3.1/helpers/pydev/pydevd.py", line 817, in do_wait_suspend
    time.sleep(0.01)
KeyboardInterrupt[0m
[34m2018-05-17 10:32:47,620 - rbus-sand calculations - 18075 - INFO - {"message": "Log is saved to /home/yoava/dev/trax_ace_factory/Projects/RBUS_SAND/log.txt", "environment": "PROD", "application": "rbus-sand calculations", "id": "ea03a0c", "process": "10.0.0.87:", "platform": "python", "severity": "INFO", "version": "unknown", "size": 269}[0m
[34m2018-05-17 10:32:48,676 - rbus-sand calculations - 18075 - INFO - {"message": "Log initialized with Syslog handler. Running on linux2 ", "environment": "PROD", "application": "rbus-sand calculations", "id": "0c13822", "process": "10.0.0.87:", "platform": "python", "severity": "INFO", "version": "unknown", "size": 249}[0m
[34m2018-05-17 10:32:48,677 - rbus-sand calculations - 18075 - INFO - {"message": "Log level set to \"INFO\"", "environment": "PROD", "application": "rbus-sand calculations", "id": "317edaa", "process": "10.0.0.87:", "platform": "python", "severity": "INFO", "version": "unknown", "size": 219}[0m
[34m2018-05-17 10:32:48,678 - rbus-sand calculations - 18075 - INFO - {"message": "Environment set to \"Prod\"", "environment": "PROD", "application": "rbus-sand calculations", "id": "4df4e24", "process": "10.0.0.87:", "platform": "python", "severity": "INFO", "version": "unknown", "size": 221}[0m
[34m2018-05-17 10:32:48,680 - rbus-sand calculations - 18075 - INFO - {"message": "Process PID is 18075", "environment": "PROD", "application": "rbus-sand calculations", "id": "7bdfe5f", "process": "10.0.0.87:", "platform": "python", "severity": "INFO", "version": "unknown", "size": 214}[0m
[34m2018-05-17 10:32:48,889 - rbus-sand calculations - 18075 - INFO - {"message": "Projects data is empty, loading data into memory cache...", "environment": "PROD", "application": "rbus-sand calculations", "id": "083b2d5", "process": "10.0.0.87:", "platform": "python", "severity": "INFO", "version": "unknown", "size": 251}[0m
[31m[1m2018-05-17 10:32:48,894 - rbus-sand calculations - 18075 - ERROR - {
    "message": "Exception unhandled was caught. Exception is : ",
    "environment": "PROD",
    "application": "rbus-sand calculations",
    "id": "de3406b",
    "process": "10.0.0.87:",
    "platform": "python",
    "severity": "ERROR",
    "version": "unknown",
    "traceback": [
        "Traceback (most recent call last):",
        "  File \"/home/yoava/miniconda/envs/garage/lib/python2.7/site-packages/Trax/Utils/Classes/System.py\", line 19, in get_all_python_files",
        "    all_files = next(os.walk(self.dir_path))[2]",
        "StopIteration"
    ],
    "size": 577
}[0m
[45m[1m[30m2018-05-17 10:32:49,600 - rbus-sand calculations - 18075 - CRITICAL - {"message": "Unhandled exception hook caught", "environment": "PROD", "application": "rbus-sand calculations", "id": "6165e0b", "process": "10.0.0.87:", "platform": "python", "severity": "CRITICAL", "version": "unknown", "size": 225}
Traceback (most recent call last):
  File "/home/yoava/dev/trax_ace_factory/Projects/RBUS_SAND/Calculations.py", line 23, in <module>
    data_provider = KEngineDataProvider(project_name)
  File "/home/yoava/miniconda/envs/garage/lib/python2.7/site-packages/Trax/Algo/Calculations/Core/DataProvider.py", line 152, in __init__
    self.orm_session = orm_session if orm_session is not None else OrmSession(project_name, writable=True)
  File "/home/yoava/miniconda/envs/garage/lib/python2.7/site-packages/Trax/Data/Orm/OrmCore.py", line 27, in __init__
    self.session = ProjectsSessions.get_session(project_name, writable, autocommit)
  File "/home/yoava/miniconda/envs/garage/lib/python2.7/site-packages/Trax/Data/Orm/OrmCore.py", line 53, in get_session
    cls.sessions.__setattr__(key_name, InnerOrmSession(project_name, writable, autocommit))
  File "/home/yoava/miniconda/envs/garage/lib/python2.7/site-packages/Trax/Data/Orm/OrmCore.py", line 72, in __init__
    project_instances = ProjectStore.get_project(project_name)
  File "/home/yoava/miniconda/envs/garage/lib/python2.7/site-packages/Trax/Data/Projects/Store.py", line 322, in get_project
    cls._check_invalidation_condition(use_cache)
  File "/home/yoava/miniconda/envs/garage/lib/python2.7/site-packages/Trax/Data/Projects/Store.py", line 99, in _check_invalidation_condition
    cls._load_data()
  File "/home/yoava/miniconda/envs/garage/lib/python2.7/site-packages/Trax/Data/Projects/Store.py", line 54, in _load_data
    conn = MongoConnector(MongoConnector.SMART, use_vault=True)
  File "/home/yoava/miniconda/envs/garage/lib/python2.7/site-packages/Trax/Mongo/Connector.py", line 319, in __init__
    self._get_credentials()
  File "/home/yoava/miniconda/envs/garage/lib/python2.7/site-packages/Trax/Mongo/Connector.py", line 372, in _get_credentials
    self._update_credentials_from_vault()
  File "/home/yoava/miniconda/envs/garage/lib/python2.7/site-packages/Trax/Mongo/Connector.py", line 421, in _update_credentials_from_vault
    user = ResourceUsers.get_user_credentials(resource_field)
  File "/home/yoava/miniconda/envs/garage/lib/python2.7/site-packages/Trax/Cloud/Services/Connector/Keys.py", line 409, in get_user_credentials
    cred = CredentialsFactory.get_credentials(resource, vault_cred_url=vault_cred_url)
  File "/home/yoava/miniconda/envs/garage/lib/python2.7/site-packages/Trax/Cloud/Services/Connector/Factory.py", line 87, in get_credentials
    token = cls.cloud_adapter.get_vault_token(force)
  File "/home/yoava/miniconda/envs/garage/lib/python2.7/site-packages/Trax/Cloud/Services/Connector/ConnectorAdapter.py", line 92, in get_vault_token
    self._login_vault_request()
  File "/home/yoava/miniconda/envs/garage/lib/python2.7/site-packages/Trax/Cloud/Services/Connector/ConnectorAdapter.py", line 67, in _login_vault_request
    result = json.loads(requests.post(url=self.login_vault_url, data=data, timeout=VAULT_TOKEN_REQUEST_TIMEOUT).text)
  File "/home/yoava/miniconda/envs/garage/lib/python2.7/site-packages/requests/api.py", line 112, in post
    return request('post', url, data=data, json=json, **kwargs)
  File "/home/yoava/miniconda/envs/garage/lib/python2.7/site-packages/requests/api.py", line 58, in request
    return session.request(method=method, url=url, **kwargs)
  File "/home/yoava/miniconda/envs/garage/lib/python2.7/site-packages/requests/sessions.py", line 502, in request
    resp = self.send(prep, **send_kwargs)
  File "/home/yoava/miniconda/envs/garage/lib/python2.7/site-packages/requests/sessions.py", line 612, in send
    r = adapter.send(request, **kwargs)
  File "/home/yoava/miniconda/envs/garage/lib/python2.7/site-packages/requests/adapters.py", line 440, in send
    timeout=timeout
  File "/home/yoava/miniconda/envs/garage/lib/python2.7/site-packages/urllib3/connectionpool.py", line 600, in urlopen
    chunked=chunked)
  File "/home/yoava/miniconda/envs/garage/lib/python2.7/site-packages/urllib3/connectionpool.py", line 379, in _make_request
    httplib_response = conn.getresponse(buffering=True)
  File "/home/yoava/miniconda/envs/garage/lib/python2.7/httplib.py", line 1045, in getresponse
    response.begin()
  File "/home/yoava/miniconda/envs/garage/lib/python2.7/httplib.py", line 409, in begin
    version, status, reason = self._read_status()
  File "/home/yoava/miniconda/envs/garage/lib/python2.7/httplib.py", line 365, in _read_status
    line = self.fp.readline(_MAXLINE + 1)
  File "/home/yoava/miniconda/envs/garage/lib/python2.7/socket.py", line 476, in readline
    data = self._sock.recv(self._rbufsize)
  File "/home/yoava/miniconda/envs/garage/lib/python2.7/site-packages/urllib3/contrib/pyopenssl.py", line 267, in recv
    rd = util.wait_for_read(self.socket, self.socket.gettimeout())
  File "/home/yoava/miniconda/envs/garage/lib/python2.7/site-packages/urllib3/util/wait.py", line 33, in wait_for_read
    return _wait_for_io_events(socks, EVENT_READ, timeout)
  File "/home/yoava/miniconda/envs/garage/lib/python2.7/site-packages/urllib3/util/wait.py", line 26, in _wait_for_io_events
    selector.select(timeout) if key[1] & events]
  File "/home/yoava/miniconda/envs/garage/lib/python2.7/site-packages/urllib3/util/selectors.py", line 438, in select
    maxevents=max_events)
  File "/home/yoava/miniconda/envs/garage/lib/python2.7/site-packages/urllib3/util/selectors.py", line 94, in _syscall_wrapper
    result = func(*args, **kwargs)
KeyboardInterrupt[0m
[34m2018-05-17 11:32:05,764 - rbus-sand calculations - 26719 - INFO - {"message": "Log is saved to /home/yoava/dev/trax_ace_factory/Projects/RBUS_SAND/log.txt", "environment": "DEV", "application": "rbus-sand calculations", "cloud": "local", "id": "e4f45c9", "process": "10.0.0.87:Local", "platform": "python", "severity": "INFO", "version": "unknown", "size": 291}[0m
[34m2018-05-17 11:32:05,775 - rbus-sand calculations - 26719 - INFO - {"message": "Log initialized with Syslog handler. Running on linux2 ", "environment": "DEV", "application": "rbus-sand calculations", "cloud": "local", "id": "5a0218e", "process": "10.0.0.87:Local", "platform": "python", "severity": "INFO", "version": "unknown", "size": 271}[0m
[34m2018-05-17 11:32:05,776 - rbus-sand calculations - 26719 - INFO - {"message": "Log level set to \"INFO\"", "environment": "DEV", "application": "rbus-sand calculations", "cloud": "local", "id": "cc39983", "process": "10.0.0.87:Local", "platform": "python", "severity": "INFO", "version": "unknown", "size": 241}[0m
[34m2018-05-17 11:32:05,778 - rbus-sand calculations - 26719 - INFO - {"message": "Environment set to \"Dev\"", "environment": "DEV", "application": "rbus-sand calculations", "cloud": "local", "id": "1df03e0", "process": "10.0.0.87:Local", "platform": "python", "severity": "INFO", "version": "unknown", "size": 242}[0m
[34m2018-05-17 11:32:05,779 - rbus-sand calculations - 26719 - INFO - {"message": "Process PID is 26719", "environment": "DEV", "application": "rbus-sand calculations", "cloud": "local", "id": "fff274d", "process": "10.0.0.87:Local", "platform": "python", "severity": "INFO", "version": "unknown", "size": 236}[0m
[34m2018-05-17 11:32:05,781 - rbus-sand calculations - 26719 - INFO - {"message": "Projects data is empty, loading data into memory cache...", "environment": "DEV", "application": "rbus-sand calculations", "cloud": "local", "id": "e08ec6a", "process": "10.0.0.87:Local", "platform": "python", "severity": "INFO", "version": "unknown", "size": 273}[0m
[43m[30m2018-05-17 11:32:05,783 - rbus-sand calculations - 26719 - WARNING - {"message": "Unable to access vault while running in dev environment.", "environment": "DEV", "application": "rbus-sand calculations", "cloud": "local", "id": "9ea9e69", "process": "10.0.0.87:Local", "platform": "python", "severity": "WARNING", "version": "unknown", "size": 272}[0m
[45m[1m[30m2018-05-17 11:32:14,196 - rbus-sand calculations - 26719 - CRITICAL - {"message": "Unhandled exception hook caught", "environment": "DEV", "application": "rbus-sand calculations", "cloud": "local", "id": "bb0cc5d", "process": "10.0.0.87:Local", "platform": "python", "severity": "CRITICAL", "version": "unknown", "size": 247}
Traceback (most recent call last):
  File "/home/yoava/dev/trax_ace_factory/Projects/RBUS_SAND/Calculations.py", line 23, in <module>
    data_provider = KEngineDataProvider(project_name)
  File "/home/yoava/dev/theGarage/Trax/Algo/Calculations/Core/DataProvider.py", line 152, in __init__
    self.orm_session = orm_session if orm_session is not None else OrmSession(project_name, writable=True)
  File "/home/yoava/dev/theGarage/Trax/Data/Orm/OrmCore.py", line 27, in __init__
    self.session = ProjectsSessions.get_session(project_name, writable, autocommit)
  File "/home/yoava/dev/theGarage/Trax/Data/Orm/OrmCore.py", line 53, in get_session
    cls.sessions.__setattr__(key_name, InnerOrmSession(project_name, writable, autocommit))
  File "/home/yoava/dev/theGarage/Trax/Data/Orm/OrmCore.py", line 72, in __init__
    project_instances = ProjectStore.get_project(project_name)
  File "/home/yoava/dev/theGarage/Trax/Data/Projects/Store.py", line 322, in get_project
    cls._check_invalidation_condition(use_cache)
  File "/home/yoava/dev/theGarage/Trax/Data/Projects/Store.py", line 99, in _check_invalidation_condition
    cls._load_data()
  File "/home/yoava/dev/theGarage/Trax/Data/Projects/Store.py", line 63, in _load_data
    for project in projects_cursor:
  File "/home/yoava/miniconda/envs/garage/lib/python2.7/site-packages/pymongo/cursor.py", line 1046, in next
    if len(self.__data) or self._refresh():
  File "/home/yoava/miniconda/envs/garage/lib/python2.7/site-packages/pymongo/cursor.py", line 970, in _refresh
    self.__batch_size))
  File "/home/yoava/miniconda/envs/garage/lib/python2.7/site-packages/pymongo/cursor.py", line 819, in __send_message
    **kwargs)
  File "/home/yoava/miniconda/envs/garage/lib/python2.7/site-packages/pymongo/mongo_client.py", line 749, in _send_message_with_response
    server = topology.select_server(selector)
  File "/home/yoava/miniconda/envs/garage/lib/python2.7/site-packages/pymongo/topology.py", line 141, in select_server
    address))
  File "/home/yoava/miniconda/envs/garage/lib/python2.7/site-packages/pymongo/topology.py", line 126, in select_servers
    self._condition.wait(common.MIN_HEARTBEAT_INTERVAL)
  File "/home/yoava/miniconda/envs/garage/lib/python2.7/threading.py", line 358, in wait
    _sleep(delay)
KeyboardInterrupt[0m
[34m2018-05-17 11:32:16,185 - rbus-sand calculations - 26801 - INFO - {"message": "Log is saved to /home/yoava/dev/trax_ace_factory/Projects/RBUS_SAND/log.txt", "environment": "PROD", "application": "rbus-sand calculations", "cloud": "AWS", "id": "e4f45c9", "process": "10.0.0.87:", "platform": "python", "severity": "INFO", "version": "unknown", "size": 285}[0m
[34m2018-05-17 11:32:17,228 - rbus-sand calculations - 26801 - INFO - {"message": "Log initialized with Syslog handler. Running on linux2 ", "environment": "PROD", "application": "rbus-sand calculations", "cloud": "AWS", "id": "5a0218e", "process": "10.0.0.87:", "platform": "python", "severity": "INFO", "version": "unknown", "size": 265}[0m
[34m2018-05-17 11:32:17,229 - rbus-sand calculations - 26801 - INFO - {"message": "Log level set to \"INFO\"", "environment": "PROD", "application": "rbus-sand calculations", "cloud": "AWS", "id": "cc39983", "process": "10.0.0.87:", "platform": "python", "severity": "INFO", "version": "unknown", "size": 235}[0m
[34m2018-05-17 11:32:17,231 - rbus-sand calculations - 26801 - INFO - {"message": "Environment set to \"Prod\"", "environment": "PROD", "application": "rbus-sand calculations", "cloud": "AWS", "id": "1df03e0", "process": "10.0.0.87:", "platform": "python", "severity": "INFO", "version": "unknown", "size": 237}[0m
[34m2018-05-17 11:32:17,233 - rbus-sand calculations - 26801 - INFO - {"message": "Process PID is 26801", "environment": "PROD", "application": "rbus-sand calculations", "cloud": "AWS", "id": "fff274d", "process": "10.0.0.87:", "platform": "python", "severity": "INFO", "version": "unknown", "size": 230}[0m
[34m2018-05-17 11:32:17,448 - rbus-sand calculations - 26801 - INFO - {"message": "Projects data is empty, loading data into memory cache...", "environment": "PROD", "application": "rbus-sand calculations", "cloud": "AWS", "id": "e08ec6a", "process": "10.0.0.87:", "platform": "python", "severity": "INFO", "version": "unknown", "size": 267}[0m
[34m2018-05-17 11:32:18,335 - rbus-sand calculations - 26801 - INFO - {"message": "get_credentials: get request returned errors: [u'entry for role yoava@TraxRetail.com not found']", "environment": "PROD", "application": "rbus-sand calculations", "cloud": "AWS", "id": "fc56a0b", "process": "10.0.0.87:", "platform": "python", "severity": "INFO", "version": "unknown", "size": 306}[0m
[34m2018-05-17 11:32:24,126 - rbus-sand calculations - 26801 - INFO - {"message": "get_credentials: get request returned errors: [u'entry for role yoava@TraxRetail.com not found']", "environment": "PROD", "application": "rbus-sand calculations", "cloud": "AWS", "id": "fc56a0b", "process": "10.0.0.87:", "platform": "python", "severity": "INFO", "version": "unknown", "size": 306}[0m
[43m[30m2018-05-17 11:32:24,129 - rbus-sand calculations - 26801 - WARNING - {"message": "get_credentials: Failed to retrieve credentials from vault: exception is :Login to vault failed 1 tiems. last login resulted errors: [u'entry for role yoava@TraxRetail.com not found']", "environment": "PROD", "application": "rbus-sand calculations", "cloud": "AWS", "id": "92a0ca6", "process": "10.0.0.87:", "platform": "python", "severity": "WARNING", "version": "unknown", "size": 393}[0m
[43m[30m2018-05-17 11:32:24,133 - rbus-sand calculations - 26801 - WARNING - {"message": "Traceback (most recent call last):\n  File \"/home/yoava/dev/theGarage/Trax/Cloud/Services/Connector/Factory.py\", line 87, in get_credentials\n    token = cls.cloud_adapter.get_vault_token(force)\n  File \"/home/yoava/dev/theGarage/Trax/Cloud/Services/Connector/ConnectorAdapter.py\", line 92, in get_vault_token\n    self._login_vault_request()\n  File \"/home/yoava/dev/theGarage/Trax/Cloud/Services/Connector/ConnectorAdapter.py\", line 68, in _login_vault_request\n    self._check_for_errors(result, retries)\n  File \"/home/yoava/dev/theGarage/Trax/Cloud/Services/Connector/ConnectorAdapter.py\", line 82, in _check_for_errors\n    return self._login_vault_request(retries - 1)\n  File \"/home/yoava/dev/theGarage/Trax/Cloud/Services/Connector/ConnectorAdapter.py\", line 68, in _login_vault_request\n    self._check_for_errors(result, retries)\n  File \"/home/yoava/dev/theGarage/Trax/Cloud/Services/Connector/ConnectorAdapter.py\", line 83, in _check_for_errors\n    raise Exception(VaultRequest.LOGIN_FAILED_ERR.format(VaultResource.RETRY_AMOUNT, errors))\nException: Login to vault failed 1 tiems. last login resulted errors: [u'entry for role yoava@TraxRetail.com not found']\n", "environment": "PROD", "application": "rbus-sand calculations", "cloud": "AWS", "id": "a2d05a8", "process": "10.0.0.87:", "platform": "python", "severity": "WARNING", "version": "unknown", "size": 1398}[0m
[34m2018-05-17 11:32:29,178 - rbus-sand calculations - 26801 - INFO - {"message": "Loaded projects data into memory cache", "environment": "PROD", "application": "rbus-sand calculations", "cloud": "AWS", "id": "07865dd", "process": "10.0.0.87:", "platform": "python", "severity": "INFO", "version": "unknown", "size": 248}[0m
[34m2018-05-17 11:32:35,302 - rbus-sand calculations - 26801 - INFO - {"message": "get_credentials: get request returned errors: [u'entry for role yoava@TraxRetail.com not found']", "environment": "PROD", "application": "rbus-sand calculations", "cloud": "AWS", "id": "fc56a0b", "process": "10.0.0.87:", "platform": "python", "severity": "INFO", "version": "unknown", "size": 306}[0m
[34m2018-05-17 11:32:36,443 - rbus-sand calculations - 26801 - INFO - {"message": "get_credentials: get request returned errors: [u'entry for role yoava@TraxRetail.com not found']", "environment": "PROD", "application": "rbus-sand calculations", "cloud": "AWS", "id": "fc56a0b", "process": "10.0.0.87:", "platform": "python", "severity": "INFO", "version": "unknown", "size": 306}[0m
[43m[30m2018-05-17 11:32:36,446 - rbus-sand calculations - 26801 - WARNING - {"message": "get_credentials: Failed to retrieve credentials from vault: exception is :Login to vault failed 1 tiems. last login resulted errors: [u'entry for role yoava@TraxRetail.com not found']", "environment": "PROD", "application": "rbus-sand calculations", "cloud": "AWS", "id": "92a0ca6", "process": "10.0.0.87:", "platform": "python", "severity": "WARNING", "version": "unknown", "size": 393}[0m
[43m[30m2018-05-17 11:32:36,449 - rbus-sand calculations - 26801 - WARNING - {"message": "Traceback (most recent call last):\n  File \"/home/yoava/dev/theGarage/Trax/Cloud/Services/Connector/Factory.py\", line 87, in get_credentials\n    token = cls.cloud_adapter.get_vault_token(force)\n  File \"/home/yoava/dev/theGarage/Trax/Cloud/Services/Connector/ConnectorAdapter.py\", line 92, in get_vault_token\n    self._login_vault_request()\n  File \"/home/yoava/dev/theGarage/Trax/Cloud/Services/Connector/ConnectorAdapter.py\", line 68, in _login_vault_request\n    self._check_for_errors(result, retries)\n  File \"/home/yoava/dev/theGarage/Trax/Cloud/Services/Connector/ConnectorAdapter.py\", line 82, in _check_for_errors\n    return self._login_vault_request(retries - 1)\n  File \"/home/yoava/dev/theGarage/Trax/Cloud/Services/Connector/ConnectorAdapter.py\", line 68, in _login_vault_request\n    self._check_for_errors(result, retries)\n  File \"/home/yoava/dev/theGarage/Trax/Cloud/Services/Connector/ConnectorAdapter.py\", line 83, in _check_for_errors\n    raise Exception(VaultRequest.LOGIN_FAILED_ERR.format(VaultResource.RETRY_AMOUNT, errors))\nException: Login to vault failed 1 tiems. last login resulted errors: [u'entry for role yoava@TraxRetail.com not found']\n", "environment": "PROD", "application": "rbus-sand calculations", "cloud": "AWS", "id": "a2d05a8", "process": "10.0.0.87:", "platform": "python", "severity": "WARNING", "version": "unknown", "size": 1398}[0m
[34m2018-05-17 11:32:39,609 - rbus-sand calculations - 26801 - INFO - {"message": "get_credentials: get request returned errors: [u'entry for role yoava@TraxRetail.com not found']", "environment": "PROD", "application": "rbus-sand calculations", "cloud": "AWS", "id": "fc56a0b", "process": "10.0.0.87:", "platform": "python", "severity": "INFO", "version": "unknown", "size": 306}[0m
